Workbook

Sheet Extraction
A1: Collaborateur | B1: 1 | C1: 11C | D1: 11N | E1: 11NC | F1: 11S | G1: 12C | H1: 12S | I1: 13 | J1: 13B | K1: 13C | L1: 13D | M1: 14B | N1: 14D | O1: 16 | P1: 16A | Q1: 16N | R1: 17 | S1: 17E | T1: 18E | U1: 18I | V1: 19 | W1: 1BBR-B | X1: 2 | Y1: 21 | Z1: 24 | AA1: 27 | AB1: 29 | AC1: 2BBR | AD1: 4 | AE1: 41N | AF1: 42N | AG1: 43N | AH1: 44 | AI1: 45 | AJ1: 46C | AK1: 46F | AL1: 46N | AM1: 47 | AN1: 47E | AO1: 49 | AP1: 5 | AQ1: 51 | AR1: 52 | AS1: 53 | AT1: 54 | AU1: 55 | AV1: 55A | AW1: 55E | AX1: 55F | AY1: 56 | AZ1: 5I | BA1: 6 | BB1: 60 | BC1: 61 | BD1: 62 | BE1: 63 | BF1: 64 | BG1: 64A | BH1: 65A | BI1: 65B | BJ1: 67 | BK1: 68 | BL1: 69 | BM1: 69P | BN1: 6DI | BO1: 6I | BP1: 71 | BQ1: 72 | BR1: 72CH | BS1: 72I | BT1: 73 | BU1: 73F | BV1: 74 | BW1: 75 | BX1: 76 | BY1: 76A | BZ1: 76B | CA1: 77 | CB1: 78 | CC1: 79 | CD1: 7I | CE1: A | CF1: A1 | CG1: A13CAL | CH1: A13RA | CI1: A14 | CJ1: A16A | CK1: A16ARA | CL1: A1CAL | CM1: A1RA | CN1: A7CAL | CO1: A7RA | CP1: A7S | CQ1: B1 | CR1: C | CS1: C1 | CT1: C13 | CU1: C7 | CV1: C73 | CW1: CCA24 | CX1: F | CY1: F1 | CZ1: F13 | DA1: F13A | DB1: F13B | DC1: F13CO | DD1: F13FSA | DE1: F14A | DF1: F1B | DG1: F1CO | DH1: F1FSA | DI1: F1VG | DJ1: F4VG | DK1: F7 | DL1: F7A | DM1: F7CO | DN1: F7VG | DO1: I | DP1: M | DQ1: P | DR1: P1 | DS1: P1A | DT1: P1EP | DU1: P1R | DV1: P1VF | DW1: P4 | DX1: P4EP | DY1: P4SD | DZ1: P4VF | EA1: P51 | EB1: P5BV | EC1: P5EP | ED1: P5P | EE1: P5T | EF1: P6A | EG1: P6BT | EH1: P6BV | EI1: P6P | EJ1: P6T | EK1: P6Z | EL1: P72A | EM1: P7C | EN1: P7COM | EO1: P7P | EP1: P7R | EQ1: P7VF | ER1: V | ES1: V1 | ET1: V4G | EU1: Z | EV1: Total
A2: Anderfuhren Sandrine | W2: 3.75 | AM2: 1.25 | AQ2: 50 | AR2: 20.5 | AS2: 1.75 | BC2: 16.25 | BE2: 1.5 | BF2: 9.75 | BG2: 1.5 | BL2: 5.75 | BM2: 10.5 | BQ2: 1.25 | BT2: 10.51 | BU2: 139 | CB2: 1.5 | CC2: 4.25 | CX2: 7.2 | DM2: 2 | EV2: 288.21
A3: Baratti Graziano | I3: 1.75 | M3: 0.25 | N3: 0.5 | O3: 0.25 | AO3: 9 | AQ3: 41.75 | AR3: 4.75 | AS3: 10.5 | AT3: 4 | AU3: 1.75 | AY3: 0.75 | BA3: 103.5 | BB3: 1.25 | BC3: 700.75 | BD3: 2.75 | BE3: 27.75 | BF3: 106.5 | BG3: 15.5 | BK3: 49.25 | BL3: 55.25 | BO3: 4.5 | BP3: 10.25 | BQ3: 15.25 | BT3: 14.25 | BX3: 4.5 | BY3: 15.25 | BZ3: 1.25 | CA3: 9 | CB3: 37 | CC3: 59.5 | CD3: 0.75 | CN3: 1.25 | CR3: 8 | CX3: 57.6 | DM3: 0.5 | DN3: 2 | DP3: 32.5 | DQ3: 55.5 | EQ3: 2.75 | ER3: 197.5 | EU3: 3 | EV3: 1669.85
A4: Bolay Valérie | B4: 104.5 | C4: 13 | D4: 49 | E4: 10.5 | F4: 121.75 | H4: 311.25 | O4: 1.75 | P4: 1 | Q4: 4 | V4: 5.5 | Y4: 5 | AA4: 9.5 | BK4: 0.25 | BP4: 19 | BT4: 6.25 | BY4: 2.25 | CB4: 28.5 | CC4: 31.5 | CE4: 122 | CJ4: 18.25 | CK4: 6.25 | CM4: 3.5 | CQ4: 7.75 | CR4: 4 | CS4: 0.75 | CX4: 49.6 | DI4: 4.75 | DP4: 29 | DQ4: 36 | DR4: 2.5 | DS4: 111.25 | DT4: 104 | DU4: 30.75 | DV4: 4 | ER4: 142.5 | ES4: 8.75 | EV4: 1410.1
A5: Castello Donja | F5: 31.5 | H5: 119.25 | BP5: 2.25 | CB5: 1 | CC5: 16 | CX5: 4 | DP5: 32 | DQ5: 7 | ER5: 36 | EU5: 4 | EV5: 253
A6: Chatelain Antonin | AD6: 21.25 | AE6: 234.5 | AF6: 442 | AH6: 23.5 | AI6: 0.5 | AJ6: 3 | AO6: 0.25 | BP6: 0.5 | BQ6: 7.13 | BY6: 24 | CA6: 1.5 | CB6: 38.25 | CC6: 29.75 | CR6: 37 | CX6: 41.6 | DQ6: 42.5 | ER6: 90.5 | EU6: 30 | EV6: 1067.73
A7: Chatenoux Didier | AD7: 27 | AE7: 387.75 | AF7: 353.5 | AG7: 268 | AI7: 3 | AJ7: 2 | AL7: 7.5 | AM7: 2.75 | AN7: 2 | AO7: 50.5 | BP7: 45 | BX7: 5.63 | CB7: 43.75 | CC7: 0.25 | CR7: 12 | CX7: 50.4 | DP7: 16 | DQ7: 53 | ER7: 131.5 | EV7: 1461.53
A8: Cosandey Philippe | EV8: 0
A9: Dos Santos Martins Carlos | AP9: 19 | AQ9: 414 | AR9: 155 | AS9: 53.75 | AT9: 50.5 | AU9: 138.5 | AX9: 12.25 | AY9: 8.25 | BQ9: 3 | BT9: 4.5 | BU9: 15.5 | CB9: 23.5 | CC9: 1.5 | CR9: 19.5 | CX9: 36 | DM9: 3 | DQ9: 14.25 | ER9: 70 | EU9: 7 | EV9: 1049
A10: Favre Corinne | B10: 294.25 | G10: 1.25 | H10: 171 | I10: 2 | J10: 0.25 | M10: 37.75 | N10: 0.5 | O10: 1.5 | P10: 19.75 | R10: 2.5 | S10: 2 | T10: 0.5 | U10: 2.5 | V10: 100.5 | X10: 16.25 | Y10: 11 | AA10: 0.75 | BP10: 18.5 | BT10: 3.75 | BW10: 0.5 | BX10: 11.51 | CA10: 32.5 | CB10: 80.25 | CC10: 73 | CF10: 1.25 | CJ10: 13 | CK10: 10.75 | CO10: 2.5 | CQ10: 2.75 | CR10: 49.75 | CS10: 5.75 | CU10: 0.5 | CW10: 5.75 | CX10: 43.2 | DK10: 1.75 | DL10: 1 | DN10: 1.75 | DP10: 15.5 | DQ10: 43.75 | DR10: 1 | DS10: 8.75 | DT10: 10.25 | DU10: 12 | EQ10: 0.5 | ER10: 128.5 | EV10: 1244.21
A11: Fleuret Thi Hanh | B11: 37.5 | I11: 12 | J11: 11 | L11: 0.25 | AC11: 1.25 | AD11: 0.25 | AO11: 4.75 | AS11: 1.5 | AT11: 1 | AU11: 0.5 | BA11: 1 | BC11: 183.5 | BE11: 0.25 | BF11: 305.75 | BH11: 278 | BK11: 80.5 | BL11: 47.5 | BM11: 15.5 | BO11: 5.75 | BQ11: 21.5 | BT11: 52.63 | BX11: 1.75 | BY11: 2.5 | BZ11: 0.25 | CB11: 14.5 | CC11: 67.25 | CH11: 4 | CR11: 8 | CX11: 50.4 | CY11: 1.5 | CZ11: 2.25 | DA11: 2.75 | DJ11: 1 | DN11: 5.25 | DO11: 10.75 | DP11: 12 | DQ11: 52.25 | DV11: 1 | DZ11: 0.5 | EA11: 2.25 | EG11: 10.75 | EQ11: 8 | ER11: 144 | EV11: 1464.78
A12: Galley Laurent | AI12: 0.75 | AO12: 3.75 | AP12: 33.5 | AQ12: 393.75 | AR12: 84.5 | AS12: 107 | AT12: 50.5 | AU12: 27.5 | AV12: 0.75 | AX12: 3.5 | AY12: 28.5 | AZ12: 1.25 | BE12: 0.5 | BQ12: 3.5 | BT12: 2.25 | BV12: 0.75 | BX12: 2 | BY12: 1.75 | CB12: 22 | CC12: 29 | CX12: 36 | DM12: 0.75 | DP12: 121 | DQ12: 8.25 | ER12: 80 | EV12: 1043
A13: Geuggis Gilles | AD13: 16.5 | AE13: 52.75 | AF13: 218.75 | AH13: 35.25 | AI13: 4 | AM13: 2 | AO13: 6.75 | BP13: 12 | BX13: 5.63 | CA13: 8.25 | CB13: 7.5 | CC13: 12.5 | CR13: 12.5 | CV13: 3.5 | CX13: 14.4 | DQ13: 1 | ER13: 10 | EV13: 423.28
A14: Harth Eric | AD14: 152.5 | AJ14: 3.75 | AM14: 8 | AO14: 0.25 | BP14: 2 | CA14: 56.75 | CB14: 47.5 | CC14: 2 | CE14: 64 | CX14: 20 | DP14: 16 | DQ14: 17.25 | DT14: 3 | DW14: 1.25 | DX14: 26.75 | DY14: 0.5 | EB14: 2.75 | EE14: 190.25 | ER14: 76 | EV14: 690.5
A15: Holenweg Pascale | B15: 10.5 | D15: 28 | F15: 251.25 | H15: 304 | P15: 33 | R15: 57 | V15: 38.5 | BP15: 9.5 | BW15: 29.25 | CB15: 9.25 | CC15: 47.25 | CQ15: 14.5 | CR15: 12 | CX15: 39.6 | DI15: 1 | DP15: 20 | DQ15: 23.75 | DS15: 5.25 | DT15: 15.75 | DV15: 50 | ER15: 144 | EV15: 1143.35
A16: Kuhn Christian | AD16: 51.5 | AE16: 79.5 | AF16: 154 | AH16: 29.75 | AI16: 3 | AJ16: 1.75 | AL16: 2.5 | AO16: 48.63 | BP16: 2 | BY16: 27.5 | CA16: 0.75 | CB16: 16 | CC16: 15.25 | CX16: 39.2 | DP16: 279.75 | DQ16: 7.75 | DW16: 0.75 | ER16: 114 | EU16: 228.75 | EV16: 1102.33
A17: Leon Gabriel | EV17: 0
A18: Merzouk Séverine | B18: 28.5 | C18: 13.25 | D18: 79 | E18: 9.25 | F18: 99 | G18: 7.75 | H18: 284 | P18: 88.75 | Q18: 6 | R18: 9 | S18: 13.25 | V18: 15.75 | BP18: 10.5 | BT18: 40 | CB18: 12.5 | CC18: 35 | CF18: 0.25 | CR18: 12 | CS18: 0.75 | CX18: 36 | CY18: 2.75 | DI18: 8.75 | DP18: 43.75 | DQ18: 41.5 | DR18: 9.75 | DT18: 18.25 | DV18: 15 | ER18: 104.5 | EU18: 4 | EV18: 1048.75
A19: Meyrat Jean-Marc | B19: 3.75 | X19: 117.5 | Y19: 108.25 | Z19: 125 | AA19: 14.25 | AB19: 4.75 | AE19: 16.25 | AP19: 486 | AX19: 5 | AZ19: 5.5 | BE19: 2.5 | BG19: 80 | BM19: 7.75 | BQ19: 4.75 | BT19: 94.38 | BU19: 43.75 | BV19: 15.25 | BW19: 11.25 | CA19: 20 | CB19: 137 | CC19: 13.5 | CR19: 29.5 | CX19: 57.6 | DP19: 46.5 | DQ19: 4.5 | EA19: 1.5 | EG19: 15 | EL19: 9.5 | EN19: 28 | ER19: 167 | EV19: 1675.48
A20: Othenin Roberto | AD20: 3.5 | AE20: 22.75 | AF20: 176 | AM20: 0.25 | AO20: 10 | BP20: 4 | BY20: 1.25 | CB20: 1 | CX20: 5.6 | DQ20: 4.75 | EV20: 229.1
A21: Paul Bertram | B21: 7.5 | G21: 0.75 | I21: 20 | J21: 70 | K21: 14.75 | L21: 3.25 | O21: 10 | AB21: 26.25 | AD21: 0.75 | AO21: 1.5 | AQ21: 6.5 | AR21: 0.5 | BA21: 7 | BC21: 17.75 | BE21: 14.25 | BF21: 0.25 | BG21: 74 | BH21: 2.75 | BI21: 49.75 | BK21: 58 | BL21: 182.25 | BM21: 15 | BO21: 23.5 | BQ21: 7.5 | BR21: 0.25 | BS21: 8.25 | BX21: 3 | BY21: 3.5 | BZ21: 0.25 | CB21: 11.5 | CC21: 60.75 | CG21: 2.75 | CL21: 2.25 | CR21: 8 | CT21: 3.5 | CX21: 36 | DC21: 28.5 | DD21: 2 | DG21: 15 | DH21: 1.5 | DM21: 1 | DN21: 0.75 | DQ21: 45.5 | DS21: 1 | EA21: 7 | EB21: 2 | EC21: 8.75 | EE21: 9.75 | EH21: 1.5 | EI21: 0.75 | EJ21: 7.25 | EM21: 1.25 | EQ21: 2.5 | ER21: 140 | ET21: 0.75 | EU21: 20 | EV21: 1050.5
A22: Pillet Anne | B22: 23.5 | I22: 1 | O22: 3.5 | P22: 1 | Y22: 2 | AD22: 20.5 | AO22: 17 | AP22: 32 | AQ22: 2.25 | AS22: 0.5 | AU22: 5.25 | AW22: 2.75 | AX22: 10 | BA22: 11.25 | BD22: 1.5 | BE22: 2 | BK22: 0.5 | BP22: 6.75 | BQ22: 41.75 | BR22: 6.25 | BS22: 1 | BT22: 1.75 | BV22: 27 | BX22: 7.25 | BY22: 2.75 | CA22: 169.75 | CB22: 426.5 | CC22: 55.25 | CE22: 219.5 | CP22: 0.5 | CR22: 8 | CX22: 57.6 | DG22: 0.5 | DL22: 1.5 | DM22: 0.25 | DP22: 226.5 | DQ22: 46.5 | DS22: 1 | DU22: 1.75 | ED22: 6.5 | EE22: 36.75 | EF22: 39 | EJ22: 48 | EO22: 35.5 | EP22: 1 | ER22: 252 | EU22: 4 | EV22: 1868.85
A23: Rérat Cédric | I23: 12.75 | V23: 0.5 | AO23: 33.25 | AQ23: 0.5 | AT23: 1 | AU23: 2.25 | AX23: 0.5 | BA23: 69.25 | BB23: 39 | BC23: 396.75 | BD23: 33.75 | BE23: 70.75 | BF23: 191 | BG23: 99.5 | BJ23: 0.75 | BK23: 14.75 | BL23: 38.5 | BM23: 0.75 | BN23: 0.5 | BO23: 1 | BP23: 4.75 | BQ23: 7.75 | BT23: 13.25 | BX23: 9.51 | BY23: 3.5 | CA23: 74.75 | CB23: 293.25 | CC23: 238.5 | CN23: 1 | CR23: 46 | CX23: 72 | DK23: 1.75 | DM23: 3.75 | DN23: 5 | DP23: 8 | DQ23: 0.75 | EF23: 109.75 | EJ23: 1.25 | EK23: 4.25 | EQ23: 4.25 | ER23: 176 | ES23: 1 | EV23: 2087.01
A24: Rossier Christophe | AD24: 54.75 | AE24: 261 | AF24: 411.5 | AH24: 64 | AI24: 13.5 | AJ24: 9.5 | AK24: 3 | AL24: 7.25 | AM24: 28.5 | AO24: 30.75 | BP24: 63.5 | BX24: 7.13 | BY24: 17 | CA24: 9 | CB24: 78.25 | CC24: 21.25 | CR24: 12 | CV24: 1.5 | CX24: 48 | DI24: 6.5 | DJ24: 7.5 | DP24: 24 | DQ24: 56.25 | DV24: 11 | DW24: 27.75 | DZ24: 18.5 | ER24: 128 | EV24: 1420.88
A25: Vukanovic Natasha | EV25: 0
A26: Walter Gamila | EV26: 0
A27: Boulsa Bénévolat | DB27: 0.75 | DF27: 3.75 | EV27: 4.5
A28: CIR Bibliothécaire | EV28: 0
A29: Etudiant Temporaire | EV29: 0
A30: Klappenbach Sacsahuaman | M30: 125.5 | N30: 8.5 | AY30: 88 | CI30: 2.5 | DE30: 2.5 | EV30: 227
A31: reliure bénévoles | BE31: 28.5 | DM31: 14.25 | EV31: 42.75
A32: Tempo Audio | EV32: 0
A33: Tempo Braille | EV33: 0
A34: Total | B34: 510 | C34: 26.25 | D34: 156 | E34: 19.75 | F34: 503.5 | G34: 9.75 | H34: 1189.5 | I34: 49.5 | J34: 81.25 | K34: 14.75 | L34: 3.5 | M34: 163.5 | N34: 9.5 | O34: 17 | P34: 143.5 | Q34: 10 | R34: 68.5 | S34: 15.25 | T34: 0.5 | U34: 2.5 | V34: 160.75 | W34: 3.75 | X34: 133.75 | Y34: 126.25 | Z34: 125 | AA34: 24.5 | AB34: 31 | AC34: 1.25 | AD34: 348.5 | AE34: 1054.5 | AF34: 1755.75 | AG34: 268 | AH34: 152.5 | AI34: 24.75 | AJ34: 20 | AK34: 3 | AL34: 17.25 | AM34: 42.75 | AN34: 2 | AO34: 216.38 | AP34: 570.5 | AQ34: 908.75 | AR34: 265.25 | AS34: 175 | AT34: 107 | AU34: 175.75 | AV34: 0.75 | AW34: 2.75 | AX34: 31.25 | AY34: 125.5 | AZ34: 6.75 | BA34: 192 | BB34: 40.25 | BC34: 1315 | BD34: 38 | BE34: 148 | BF34: 613.25 | BG34: 270.5 | BH34: 280.75 | BI34: 49.75 | BJ34: 0.75 | BK34: 203.25 | BL34: 329.25 | BM34: 49.5 | BN34: 0.5 | BO34: 34.75 | BP34: 210.5 | BQ34: 113.38 | BR34: 6.5 | BS34: 9.25 | BT34: 243.52 | BU34: 198.25 | BV34: 43 | BW34: 41 | BX34: 57.91 | BY34: 101.25 | BZ34: 1.75 | CA34: 382.25 | CB34: 1330.5 | CC34: 813.25 | CD34: 0.75 | CE34: 405.5 | CF34: 1.5 | CG34: 2.75 | CH34: 4 | CI34: 2.5 | CJ34: 31.25 | CK34: 17 | CL34: 2.25 | CM34: 3.5 | CN34: 2.25 | CO34: 2.5 | CP34: 0.5 | CQ34: 25 | CR34: 278.25 | CS34: 7.25 | CT34: 3.5 | CU34: 0.5 | CV34: 5 | CW34: 5.75 | CX34: 802 | CY34: 4.25 | CZ34: 2.25 | DA34: 2.75 | DB34: 0.75 | DC34: 28.5 | DD34: 2 | DE34: 2.5 | DF34: 3.75 | DG34: 15.5 | DH34: 1.5 | DI34: 21 | DJ34: 8.5 | DK34: 3.5 | DL34: 2.5 | DM34: 25.5 | DN34: 14.75 | DO34: 10.75 | DP34: 922.5 | DQ34: 562 | DR34: 13.25 | DS34: 127.25 | DT34: 151.25 | DU34: 44.5 | DV34: 81 | DW34: 29.75 | DX34: 26.75 | DY34: 0.5 | DZ34: 19 | EA34: 10.75 | EB34: 4.75 | EC34: 8.75 | ED34: 6.5 | EE34: 236.75 | EF34: 148.75 | EG34: 25.75 | EH34: 1.5 | EI34: 0.75 | EJ34: 56.5 | EK34: 4.25 | EL34: 9.5 | EM34: 1.25 | EN34: 28 | EO34: 35.5 | EP34: 1 | EQ34: 18 | ER34: 2332 | ES34: 9.75 | ET34: 0.75 | EU34: 300.75 | EV34: 23965.69

Sheet Heures épurées
A1: Collaborateur | B1: 1 | C1: 11C | D1: 11N | E1: 11NC | F1: 11S | G1: 12C | H1: 12S | I1: 13 | J1: 13B | K1: 13C | L1: 13D | M1: 14B | N1: 14D | O1: 16 | P1: 16A | Q1: 16N | R1: 17 | S1: 17E | T1: 18E | U1: 18I | V1: 19 | W1: 1BBR-B | X1: 2 | Y1: 21 | Z1: 24 | AA1: 27 | AB1: 29 | AC1: 2BBR | AD1: 4 | AE1: 41N | AF1: 42N | AG1: 43N | AH1: 44 | AI1: 45 | AJ1: 46C | AK1: 46F | AL1: 46N | AM1: 47 | AN1: 47E | AO1: 49 | AP1: 5 | AQ1: 51 | AR1: 52 | AS1: 53 | AT1: 54 | AU1: 55 | AV1: 55A | AW1: 55E | AX1: 55F | AY1: 56 | AZ1: 5I | BA1: 6 | BB1: 60 | BC1: 61 | BD1: 62 | BE1: 63 | BF1: 64 | BG1: 64A | BH1: 65A | BI1: 65B | BJ1: 67 | BK1: 68 | BL1: 69 | BM1: 69P | BN1: 6DI | BO1: 6I | BP1: 71 | BQ1: 72 | BR1: 72CH | BS1: 72I | BT1: 73 | BU1: 73F | BV1: 74 | BW1: 75 | BX1: 76 | BY1: 76A | BZ1: 76B | CA1: 77 | CB1: 78 | CC1: 79 | CD1: 7I | CE1: A | CF1: A1 | CG1: A13CAL | CH1: A13RA | CI1: A14 | CJ1: A16A | CK1: A16ARA | CL1: A1CAL | CM1: A1RA | CN1: A7CAL | CO1: A7RA | CP1: A7S | CQ1: B1 | CR1: C | CS1: C1 | CT1: C13 | CU1: C7 | CV1: C73 | CW1: CCA24 | CX1: F | CY1: F1 | CZ1: F13 | DA1: F13A | DB1: F13B | DC1: F13CO | DD1: F13FSA | DE1: F14A | DF1: F1B | DG1: F1CO | DH1: F1FSA | DI1: F1VG | DJ1: F4VG | DK1: F7 | DL1: F7A | DM1: F7CO | DN1: F7VG | DO1: I | DP1: M | DQ1: P | DR1: P1 | DS1: P1A | DT1: P1EP | DU1: P1R | DV1: P1VF | DW1: P4 | DX1: P4EP | DY1: P4SD | DZ1: P4VF | EA1: P51 | EB1: P5BV | EC1: P5EP | ED1: P5P | EE1: P5T | EF1: P6A | EG1: P6BT | EH1: P6BV | EI1: P6P | EJ1: P6T | EK1: P6Z | EL1: P72A | EM1: P7C | EN1: P7COM | EO1: P7P | EP1: P7R | EQ1: P7VF | ER1: V | ES1: V1 | ET1: V4G | EU1: Z | EV1: Total
A2: Anderfuhren Sandrine | W2: 3.75 | AM2: 1.25 | AQ2: 50 | AR2: 20.5 | AS2: 1.75 | BC2: 16.25 | BE2: 1.5 | BF2: 9.75 | BG2: 1.5 | BL2: 5.75 | BM2: 10.5 | BQ2: 1.25 | BT2: 10.51 | BU2: 139 | CB2: 1.5 | CC2: 4.25 | CX2: 7.2 | DM2: 2 | EV2: =SUM(B2:EU2) -> 288.21
A3: Baratti Graziano | I3: 1.75 | M3: 0.25 | N3: 0.5 | O3: 0.25 | AO3: 9 | AQ3: 41.75 | AR3: 4.75 | AS3: 10.5 | AT3: 4 | AU3: 1.75 | AY3: 0.75 | BA3: 103.5 | BB3: 1.25 | BC3: 700.75 | BD3: 2.75 | BE3: 27.75 | BF3: 106.5 | BG3: 15.5 | BK3: 49.25 | BL3: 55.25 | BO3: 4.5 | BP3: 10.25 | BQ3: 15.25 | BT3: 14.25 | BX3: 4.5 | BY3: 15.25 | BZ3: 1.25 | CA3: 9 | CB3: 37 | CC3: 59.5 | CD3: 0.75 | CN3: 1.25 | CR3: 8 | CX3: 57.6 | DM3: 0.5 | DN3: 2 | DP3: 32.5 | DQ3: 55.5 | EQ3: 2.75 | ER3: 197.5 | EU3: 3 | EV3: =SUM(B3:EU3) -> 1669.85
A4: Bolay Valérie | B4: 104.5 | C4: 13 | D4: 49 | E4: 10.5 | F4: 121.75 | H4: 311.25 | O4: 1.75 | P4: 1 | Q4: 4 | V4: 5.5 | Y4: 5 | AA4: 9.5 | BK4: 0.25 | BP4: 19 | BT4: 6.25 | BY4: 2.25 | CB4: 28.5 | CC4: 31.5 | CE4: 122 | CJ4: 18.25 | CK4: 6.25 | CM4: 3.5 | CQ4: 7.75 | CR4: 4 | CS4: 0.75 | CX4: 49.6 | DI4: 4.75 | DP4: 29 | DQ4: 36 | DR4: 2.5 | DS4: 111.25 | DT4: 104 | DU4: 30.75 | DV4: 4 | ER4: 142.5 | ES4: 8.75 | EV4: =SUM(B4:EU4) -> 1410.1
A5: Castello Donja | F5: 31.5 | H5: 119.25 | BP5: 2.25 | CB5: 1 | CC5: 16 | CX5: 4 | DP5: 32 | DQ5: 7 | ER5: 36 | EU5: 4 | EV5: =SUM(B5:EU5) -> 253
A6: Chatelain Antonin | AD6: 21.25 | AE6: 234.5 | AF6: 442 | AH6: 23.5 | AI6: 0.5 | AJ6: 3 | AO6: 0.25 | BP6: 0.5 | BQ6: 7.13 | BY6: 24 | CA6: 1.5 | CB6: 38.25 | CC6: 29.75 | CR6: 37 | CX6: 41.6 | DQ6: 42.5 | ER6: 90.5 | EU6: 30 | EV6: =SUM(B6:EU6) -> 1067.73
A7: Chatenoux Didier | AD7: 27 | AE7: 387.75 | AF7: 353.5 | AG7: 268 | AI7: 3 | AJ7: 2 | AL7: 7.5 | AM7: 2.75 | AN7: 2 | AO7: 50.5 | BP7: 45 | BX7: 5.63 | CB7: 43.75 | CC7: 0.25 | CR7: 12 | CX7: 50.4 | DP7: 16 | DQ7: 53 | ER7: 131.5 | EV7: =SUM(B7:EU7) -> 1461.53
A8: Dos Santos Martins Carlos | AP8: 19 | AQ8: 414 | AR8: 155 | AS8: 53.75 | AT8: 50.5 | AU8: 138.5 | AX8: 12.25 | AY8: 8.25 | BQ8: 3 | BT8: 4.5 | BU8: 15.5 | CB8: 23.5 | CC8: 1.5 | CR8: 19.5 | CX8: 36 | DM8: 3 | DQ8: 14.25 | ER8: 70 | EU8: 7 | EV8: =SUM(B8:EU8) -> 1049
A9: Favre Corinne | B9: 294.25 | G9: 1.25 | H9: 171 | I9: 2 | J9: 0.25 | M9: 37.75 | N9: 0.5 | O9: 1.5 | P9: 19.75 | R9: 2.5 | S9: 2 | T9: 0.5 | U9: 2.5 | V9: 100.5 | X9: 16.25 | Y9: 11 | AA9: 0.75 | BP9: 18.5 | BT9: 3.75 | BW9: 0.5 | BX9: 11.51 | CA9: 32.5 | CB9: 80.25 | CC9: 73 | CF9: 1.25 | CJ9: 13 | CK9: 10.75 | CO9: 2.5 | CQ9: 2.75 | CR9: 49.75 | CS9: 5.75 | CU9: 0.5 | CW9: 5.75 | CX9: 43.2 | DK9: 1.75 | DL9: 1 | DN9: 1.75 | DP9: 15.5 | DQ9: 43.75 | DR9: 1 | DS9: 8.75 | DT9: 10.25 | DU9: 12 | EQ9: 0.5 | ER9: 128.5 | EV9: =SUM(B9:EU9) -> 1244.21
A10: Fleuret Thi Hanh | B10: 37.5 | I10: 12 | J10: 11 | L10: 0.25 | AC10: 1.25 | AD10: 0.25 | AO10: 4.75 | AS10: 1.5 | AT10: 1 | AU10: 0.5 | BA10: 1 | BC10: 183.5 | BE10: 0.25 | BF10: 305.75 | BH10: 278 | BK10: 80.5 | BL10: 47.5 | BM10: 15.5 | BO10: 5.75 | BQ10: 21.5 | BT10: 52.63 | BX10: 1.75 | BY10: 2.5 | BZ10: 0.25 | CB10: 14.5 | CC10: 67.25 | CH10: 4 | CR10: 8 | CX10: 50.4 | CY10: 1.5 | CZ10: 2.25 | DA10: 2.75 | DJ10: 1 | DN10: 5.25 | DO10: 10.75 | DP10: 12 | DQ10: 52.25 | DV10: 1 | DZ10: 0.5 | EA10: 2.25 | EG10: 10.75 | EQ10: 8 | ER10: 144 | EV10: =SUM(B10:EU10) -> 1464.78
A11: Galley Laurent | AI11: 0.75 | AO11: 3.75 | AP11: 33.5 | AQ11: 393.75 | AR11: 84.5 | AS11: 107 | AT11: 50.5 | AU11: 27.5 | AV11: 0.75 | AX11: 3.5 | AY11: 28.5 | AZ11: 1.25 | BE11: 0.5 | BQ11: 3.5 | BT11: 2.25 | BV11: 0.75 | BX11: 2 | BY11: 1.75 | CB11: 22 | CC11: 29 | CX11: 36 | DM11: 0.75 | DP11: 121 | DQ11: 8.25 | ER11: 80 | EV11: =SUM(B11:EU11) -> 1043
A12: Geuggis Gilles | AD12: 16.5 | AE12: 52.75 | AF12: 218.75 | AH12: 35.25 | AI12: 4 | AM12: 2 | AO12: 6.75 | BP12: 12 | BX12: 5.63 | CA12: 8.25 | CB12: 7.5 | CC12: 12.5 | CR12: 12.5 | CV12: 3.5 | CX12: 14.4 | DQ12: 1 | ER12: 10 | EV12: =SUM(B12:EU12) -> 423.28
A13: Harth Eric | AD13: 152.5 | AJ13: 3.75 | AM13: 8 | AO13: 0.25 | BP13: 2 | CA13: 56.75 | CB13: 47.5 | CC13: 2 | CE13: 64 | CX13: 20 | DP13: 16 | DQ13: 17.25 | DT13: 3 | DW13: 1.25 | DX13: 26.75 | DY13: 0.5 | EB13: 2.75 | EE13: 190.25 | ER13: 76 | EV13: =SUM(B13:EU13) -> 690.5
A14: Holenweg Pascale | B14: 10.5 | D14: 28 | F14: 251.25 | H14: 304 | P14: 33 | R14: 57 | V14: 38.5 | BP14: 9.5 | BW14: 29.25 | CB14: 9.25 | CC14: 47.25 | CQ14: 14.5 | CR14: 12 | CX14: 39.6 | DI14: 1 | DP14: 20 | DQ14: 23.75 | DS14: 5.25 | DT14: 15.75 | DV14: 50 | ER14: 144 | EV14: =SUM(B14:EU14) -> 1143.35
A15: Kuhn Christian | AD15: 51.5 | AE15: 79.5 | AF15: 154 | AH15: 29.75 | AI15: 3 | AJ15: 1.75 | AL15: 2.5 | AO15: 48.63 | BP15: 2 | BY15: 27.5 | CA15: 0.75 | CB15: 16 | CC15: 15.25 | CX15: 39.2 | DP15: 279.75 | DQ15: 7.75 | DW15: 0.75 | ER15: 114 | EU15: 228.75 | EV15: =SUM(B15:EU15) -> 1102.33
A16: Merzouk Séverine | B16: 28.5 | C16: 13.25 | D16: 79 | E16: 9.25 | F16: 99 | G16: 7.75 | H16: 284 | P16: 88.75 | Q16: 6 | R16: 9 | S16: 13.25 | V16: 15.75 | BP16: 10.5 | BT16: 40 | CB16: 12.5 | CC16: 35 | CF16: 0.25 | CR16: 12 | CS16: 0.75 | CX16: 36 | CY16: 2.75 | DI16: 8.75 | DP16: 43.75 | DQ16: 41.5 | DR16: 9.75 | DT16: 18.25 | DV16: 15 | ER16: 104.5 | EU16: 4 | EV16: =SUM(B16:EU16) -> 1048.75
A17: Meyrat Jean-Marc | B17: 3.75 | X17: 117.5 | Y17: 108.25 | Z17: 125 | AA17: 14.25 | AB17: 4.75 | AE17: 16.25 | AP17: 486 | AX17: 5 | AZ17: 5.5 | BE17: 2.5 | BG17: 80 | BM17: 7.75 | BQ17: 4.75 | BT17: 94.38 | BU17: 43.75 | BV17: 15.25 | BW17: 11.25 | CA17: 20 | CB17: 137 | CC17: 13.5 | CR17: 29.5 | CX17: 57.6 | DP17: 46.5 | DQ17: 4.5 | EA17: 1.5 | EG17: 15 | EL17: 9.5 | EN17: 28 | ER17: 167 | EV17: =SUM(B17:EU17) -> 1675.48
A18: Othenin Roberto | AD18: 3.5 | AE18: 22.75 | AF18: 176 | AM18: 0.25 | AO18: 10 | BP18: 4 | BY18: 1.25 | CB18: 1 | CX18: 5.6 | DQ18: 4.75 | EV18: =SUM(B18:EU18) -> 229.1
A19: Paul Bertram | B19: 7.5 | G19: 0.75 | I19: 20 | J19: 70 | K19: 14.75 | L19: 3.25 | O19: 10 | AB19: 26.25 | AD19: 0.75 | AO19: 1.5 | AQ19: 6.5 | AR19: 0.5 | BA19: 7 | BC19: 17.75 | BE19: 14.25 | BF19: 0.25 | BG19: 74 | BH19: 2.75 | BI19: 49.75 | BK19: 58 | BL19: 182.25 | BM19: 15 | BO19: 23.5 | BQ19: 7.5 | BR19: 0.25 | BS19: 8.25 | BX19: 3 | BY19: 3.5 | BZ19: 0.25 | CB19: 11.5 | CC19: 60.75 | CG19: 2.75 | CL19: 2.25 | CR19: 8 | CT19: 3.5 | CX19: 36 | DC19: 28.5 | DD19: 2 | DG19: 15 | DH19: 1.5 | DM19: 1 | DN19: 0.75 | DQ19: 45.5 | DS19: 1 | EA19: 7 | EB19: 2 | EC19: 8.75 | EE19: 9.75 | EH19: 1.5 | EI19: 0.75 | EJ19: 7.25 | EM19: 1.25 | EQ19: 2.5 | ER19: 140 | ET19: 0.75 | EU19: 20 | EV19: =SUM(B19:EU19) -> 1050.5
A20: Pillet Anne | B20: 23.5 | I20: 1 | O20: 3.5 | P20: 1 | Y20: 2 | AD20: 20.5 | AO20: 17 | AP20: 32 | AQ20: 2.25 | AS20: 0.5 | AU20: 5.25 | AW20: 2.75 | AX20: 10 | BA20: 11.25 | BD20: 1.5 | BE20: 2 | BK20: 0.5 | BP20: 6.75 | BQ20: 41.75 | BR20: 6.25 | BS20: 1 | BT20: 1.75 | BV20: 27 | BX20: 7.25 | BY20: 2.75 | CA20: 169.75 | CB20: 426.5 | CC20: 55.25 | CE20: 219.5 | CP20: 0.5 | CR20: 8 | CX20: 57.6 | DG20: 0.5 | DL20: 1.5 | DM20: 0.25 | DP20: 226.5 | DQ20: 46.5 | DS20: 1 | DU20: 1.75 | ED20: 6.5 | EE20: 36.75 | EF20: 39 | EJ20: 48 | EO20: 35.5 | EP20: 1 | ER20: 252 | EU20: 4 | EV20: =SUM(B20:EU20) -> 1868.85
A21: Rérat Cédric | I21: 12.75 | V21: 0.5 | AO21: 33.25 | AQ21: 0.5 | AT21: 1 | AU21: 2.25 | AX21: 0.5 | BA21: 69.25 | BB21: 39 | BC21: 396.75 | BD21: 33.75 | BE21: 70.75 | BF21: 191 | BG21: 99.5 | BJ21: 0.75 | BK21: 14.75 | BL21: 38.5 | BM21: 0.75 | BN21: 0.5 | BO21: 1 | BP21: 4.75 | BQ21: 7.75 | BT21: 13.25 | BX21: 9.51 | BY21: 3.5 | CA21: 74.75 | CB21: 293.25 | CC21: 238.5 | CN21: 1 | CR21: 46 | CX21: 72 | DK21: 1.75 | DM21: 3.75 | DN21: 5 | DP21: 8 | DQ21: 0.75 | EF21: 109.75 | EJ21: 1.25 | EK21: 4.25 | EQ21: 4.25 | ER21: 176 | ES21: 1 | EV21: =SUM(B21:EU21) -> 2087.01
A22: Rossier Christophe | AD22: 54.75 | AE22: 261 | AF22: 411.5 | AH22: 64 | AI22: 13.5 | AJ22: 9.5 | AK22: 3 | AL22: 7.25 | AM22: 28.5 | AO22: 30.75 | BP22: 63.5 | BX22: 7.13 | BY22: 17 | CA22: 9 | CB22: 78.25 | CC22: 21.25 | CR22: 12 | CV22: 1.5 | CX22: 48 | DI22: 6.5 | DJ22: 7.5 | DP22: 24 | DQ22: 56.25 | DV22: 11 | DW22: 27.75 | DZ22: 18.5 | ER22: 128 | EV22: =SUM(B22:EU22) -> 1420.88
A23: Boulsa Bénévolat | DB23: 0.75 | DF23: 3.75 | EV23: =SUM(B23:EU23) -> 4.5
A24: Klappenbach Sacsahuaman | M24: 125.5 | N24: 8.5 | AY24: 88 | CI24: 2.5 | DE24: 2.5 | EV24: =SUM(B24:EU24) -> 227
A25: reliure bénévoles | BE25: 28.5 | DM25: 14.25 | EV25: =SUM(B25:EU25) -> 42.75
A26: Total | B26: =SUM(B2:B25) -> 510 | C26: =SUM(C2:C25) -> 26.25 | D26: =SUM(D2:D25) -> 156 | E26: =SUM(E2:E25) -> 19.75 | F26: =SUM(F2:F25) -> 503.5 | G26: =SUM(G2:G25) -> 9.75 | H26: =SUM(H2:H25) -> 1189.5 | I26: =SUM(I2:I25) -> 49.5 | ... EU26: =SUM(EU2:EU25) -> 300.75 | EV26: =SUM(B26:EU26) -> 23965.69

Sheet Heures brutes
A1: Collaborateur | B1: 1 | C1: 11C | D1: 11N | E1: 11NC | F1: 11S | G1: 12C | H1: 12S | I1: 13 | J1: 13B | K1: 13C | L1: 13D | M1: 14B | N1: 14D | O1: 16 | P1: 16A | Q1: 16N | R1: 17 | S1: 17E | T1: 18E | U1: 18I | V1: 19 | W1: 1BBR-B | X1: 2 | Y1: 21 | Z1: 24 | AA1: 27 | AB1: 29 | AC1: 2BBR | AD1: 4 | AE1: 41N | AF1: 42N | AG1: 43N | AH1: 44 | AI1: 45 | AJ1: 46C | AK1: 46F | AL1: 46N | AM1: 47 | AN1: 47E | AO1: 49 | AP1: 5 | AQ1: 51 | AR1: 52 | AS1: 53 | AT1: 54 | AU1: 55 | AV1: 55A | AW1: 55E | AX1: 55F | AY1: 56 | AZ1: 5I | BA1: 6 | BB1: 60 | BC1: 61 | BD1: 62 | BE1: 63 | BF1: 64 | BG1: 64A | BH1: 65A | BI1: 65B | BJ1: 67 | BK1: 68 | BL1: 69 | BM1: 69P | BN1: 6DI | BO1: 6I | BP1: 71 | BQ1: 72 | BR1: 72CH | BS1: 72I | BT1: 73 | BU1: 73F | BV1: 74 | BW1: 75 | BX1: 76 | BY1: 76A | BZ1: 76B | CA1: 77 | CB1: 78 | CC1: 79 | CD1: 7I | CE1: A | CF1: A1 | CG1: A13CAL | CH1: A13RA | CI1: A14 | CJ1: A16A | CK1: A16ARA | CL1: A1CAL | CM1: A1RA | CN1: A7CAL | CO1: A7RA | CP1: A7S | CQ1: B1 | CR1: C | CS1: C1 | CT1: C13 | CU1: C7 | CV1: C73 | CW1: CCA24 | CX1: F | CY1: F1 | CZ1: F13 | DA1: F13A | DB1: F13B | DC1: F13CO | DD1: F13FSA | DE1: F14A | DF1: F1B | DG1: F1CO | DH1: F1FSA | DI1: F1VG | DJ1: F4VG | DK1: F7 | DL1: F7A | DM1: F7CO | DN1: F7VG | DO1: I | DP1: M | DQ1: P | DR1: P1 | DS1: P1A | DT1: P1EP | DU1: P1R | DV1: P1VF | DW1: P4 | DX1: P4EP | DY1: P4SD | DZ1: P4VF | EA1: P51 | EB1: P5BV | EC1: P5EP | ED1: P5P | EE1: P5T | EF1: P6A | EG1: P6BT | EH1: P6BV | EI1: P6P | EJ1: P6T | EK1: P6Z | EL1: P72A | EM1: P7C | EN1: P7COM | EO1: P7P | EP1: P7R | EQ1: P7VF | ER1: V | ES1: V1 | ET1: V4G | EU1: Z | EV1: Total
A2: Anderfuhren Sandrine | B2: 3.75 | AM2: 1.25 | AQ2: 50 | AR2: 20.5 | AS2: 1.75 | BC2: 16.25 | BE2: 1.5 | BF2: 9.75 | BG2: 1.5 | BL2: 5.75 | BM2: 10.5 | BQ2: 1.25 | BT2: 10.51 | BU2: 139 | CB2: 1.5 | CC2: 4.25 | CX2: 7.2 | DM2: 2 | EV2: =SUM(B2:EU2) -> 288.21 | EW2: 288.21
A3: Baratti Graziano | I3: 1.75 | M3: 0.25 | N3: 0.5 | O3: 0.25 | AO3: 9 | AQ3: 41.75 | AR3: 4.75 | AS3: 10.5 | AT3: 4 | AU3: 1.75 | AY3: 0.75 | BA3: 103.5 | BB3: 1.25 | BC3: 700.75 | BD3: 2.75 | BE3: 27.75 | BF3: 106.5 | BG3: 15.5 | BK3: 49.25 | BL3: 55.25 | BO3: 4.5 | BP3: 10.25 | BQ3: 15.25 | BT3: 14.25 | BX3: 4.5 | BY3: 15.25 | BZ3: 1.25 | CA3: 9 | CB3: 37 | CC3: 59.5 | CD3: 0.75 | CN3: 1.25 | CR3: 8 | CX3: 57.6 | DM3: 0.5 | DN3: 2 | DP3: 32.5 | DQ3: 55.5 | EQ3: 2.75 | ER3: 197.5 | EU3: 3 | EV3: =SUM(B3:EU3) -> 1669.85 | EW3: 1669.85
A4: Bolay Valérie | B4: 104.5 | C4: 13 | D4: 49 | E4: 10.5 | F4: 121.75 | H4: 311.25 | O4: 1.75 | P4: 1 | Q4: 4 | V4: 5.5 | Y4: 5 | AA4: 9.5 | BK4: 0.25 | BP4: 19 | BT4: 6.25 | BY4: 2.25 | CB4: 28.5 | CC4: 31.5 | CE4: 122 | CJ4: 18.25 | CK4: 6.25 | CM4: 3.5 | CQ4: 7.75 | CR4: 4 | CS4: 0.75 | CX4: 49.6 | DI4: 4.75 | DP4: 29 | DQ4: 36 | DR4: 2.5 | DS4: 111.25 | DT4: 104 | DU4: 30.75 | DV4: 4 | ER4: 142.5 | ES4: 8.75 | EV4: =SUM(B4:EU4) -> 1410.1 | EW4: 1410.1 | FC4: Pour les salariés mensualisés : 1 plein temps = | FG4: 2088 | FH4: A évaluer annuellement (cf circulaire | FK4: R:\COLLABORATIONS_(nationales)\Groupe-des-bibliotheques-suisses(ex_Consortium)\Reportint-controling\comment-decompter-Precisions apres visites des bibliotheques 2015.docx
A5: Castello Donja | F5: 31.5 | H5: 119.25 | BP5: 2.25 | CB5: 1 | CC5: 16 | CX5: 4 | DP5: 32 | DQ5: 7 | ER5: 36 | EU5: 4 | EV5: =SUM(B5:EU5) -> 253 | EW5: 253 | EX5: total des heures payées sur salaire mensuel : | FB5: =SUM(EV2:EV22) -> 23691.44 | FC5: postes à plein temps = | FE5: =FB5/$FG$4 -> 11.346475 | FH5: Pour 2015, considérer 2088 (cf heures dues de CR à 100%)
A6: Chatelain Antonin | AD6: 21.25 | AE6: 234.5 | AF6: 442 | AH6: 23.5 | AI6: 0.5 | AJ6: 3 | AO6: 0.25 | BP6: 0.5 | BQ6: 7.13 | BY6: 24 | CA6: 1.5 | CB6: 38.25 | CC6: 29.75 | CR6: 37 | CX6: 41.6 | DQ6: 42.5 | ER6: 90.5 | EU6: 30 | EV6: =SUM(B6:EU6) -> 1067.73 | EW6: 1067.73
A7: Chatenoux Didier | AD7: 27 | AE7: 387.75 | AF7: 353.5 | AG7: 268 | AI7: 3 | AJ7: 2 | AL7: 7.5 | AM7: 2.75 | AN7: 2 | AO7: 50.5 | BP7: 45 | BX7: 5.63 | CB7: 43.75 | CC7: 0.25 | CR7: 12 | CX7: 50.4 | DP7: 16 | DQ7: 53 | ER7: 131.5 | EV7: =SUM(B7:EU7) -> 1461.53 | EW7: 1461.53
A8: Dos Santos Martins Carlos | AP8: 19 | AQ8: 414 | AR8: 155 | AS8: 53.75 | AT8: 50.5 | AU8: 138.5 | AX8: 12.25 | AY8: 8.25 | BQ8: 3 | BT8: 4.5 | BU8: 15.5 | CB8: 23.5 | CC8: 1.5 | CR8: 19.5 | CX8: 36 | DM8: 3 | DQ8: 14.25 | ER8: 70 | EU8: 7 | EV8: =SUM(B8:EU8) -> 1049 | EW8: 1049 | FC8: Pour les salariés payés à l'heure : 1 plein temps = | FG8: 1900 | FH8: Cf doc de fonctionnement | FJ8: ..\Explications données du reporting 2015-2018 V 16.11.2015.docx
A9: Favre Corinne | B9: 294.25 | G9: 1.25 | H9: 171 | I9: 2 | J9: 0.25 | M9: 37.75 | N9: 0.5 | O9: 1.5 | P9: 19.75 | R9: 2.5 | S9: 2 | T9: 0.5 | U9: 2.5 | V9: 100.5 | X9: 16.25 | Y9: 11 | AA9: 0.75 | BP9: 18.5 | BT9: 3.75 | BW9: 0.5 | BX9: 11.51 | CA9: 32.5 | CB9: 80.25 | CC9: 73 | CF9: 1.25 | CJ9: 13 | CK9: 10.75 | CO9: 2.5 | CQ9: 2.75 | CR9: 49.75 | CS9: 5.75 | CU9: 0.5 | CW9: 5.75 | CX9: 43.2 | DK9: 1.75 | DL9: 1 | DN9: 1.75 | DP9: 15.5 | DQ9: 43.75 | DR9: 1 | DS9: 8.75 | DT9: 10.25 | DU9: 12 | EQ9: 0.5 | ER9: 128.5 | EV9: =SUM(B9:EU9) -> 1244.21 | EW9: 1244.21 | EX9: total des heures payées sur salaire horaire : | FB9: =SUM(EV23:EV25) -> 831.45 | FC9: postes à plein temps = | FE9: =FB9/$FG$8 -> 0.43760526
A10: Galley Laurent | AI10: 0.75 | AO10: 3.75 | AP10: 33.5 | AQ10: 393.75 | AR10: 84.5 | AS10: 107 | AT10: 50.5 | AU10: 27.5 | AV10: 0.75 | AX10: 3.5 | AY10: 28.5 | AZ10: 1.25 | BE10: 0.5 | BQ10: 3.5 | BT10: 2.25 | BV10: 0.75 | BX10: 2 | BY10: 1.75 | CB10: 22 | CC10: 29 | CX10: 36 | DM10: 0.75 | DP10: 121 | DQ10: 8.25 | ER10: 80 | EV10: =SUM(B10:EU10) -> 1043 | EW10: 1043
A11: Geuggis Gilles | AD11: 16.5 | AE11: 52.75 | AF11: 218.75 | AH11: 35.25 | AI11: 4 | AM11: 2 | AO11: 6.75 | BP11: 12 | BX11: 5.63 | CA11: 8.25 | CB11: 7.5 | CC11: 12.5 | CR11: 12.5 | CV11: 3.5 | CX11: 14.4 | DQ11: 1 | ER11: 10 | EV11: =SUM(B11:EU11) -> 423.28 | EW11: 423.28 | FE11: =FE9+FE5 -> 11.78408
A12: Harth Eric | AD12: 152.5 | AJ12: 3.75 | AM12: 8 | AO12: 0.25 | BP12: 2 | CA12: 56.75 | CB12: 47.5 | CC12: 2 | CE12: 64 | CX12: 20 | DP12: 16 | DQ12: 17.25 | DT12: 3 | DW12: 1.25 | DX12: 26.75 | DY12: 0.5 | EB12: 2.75 | EE12: 190.25 | ER12: 76 | EV12: =SUM(B12:EU12) -> 690.5 | EW12: 690.5 | EX12: pour vérif | FC12: Total des activités
A13: Holenweg Pascale | B13: 10.5 | D13: 28 | F13: 251.25 | H13: 304 | P13: 33 | R13: 57 | V13: 38.5 | BP13: 9.5 | BW13: 29.25 | CB13: 9.25 | CC13: 47.25 | CQ13: 14.5 | CR13: 12 | CX13: 39.6 | DI13: 1 | DP13: 20 | DQ13: 23.75 | DS13: 5.25 | DT13: 15.75 | DV13: 50 | ER13: 144 | EV13: =SUM(B13:EU13) -> 1143.35 | EW13: 1143.35 | EX13: =SUM(EV2:EV25) -> 24522.89 | EY13: =FB5+FB9 -> 24522.89 | EZ13: Professionnels : | FB13: =EV27 -> 24522.89 | FC13: postes à plein temps = | FE13: =FE5+FE9 -> 11.78408
A14: Kuhn Christian | AD14: 51.5 | AE14: 79.5 | AF14: 154 | AH14: 29.75 | AI14: 3 | AJ14: 1.75 | AL14: 2.5 | AO14: 48.63 | BP14: 2 | BY14: 27.5 | CA14: 0.75 | CB14: 16 | CC14: 15.25 | CX14: 39.2 | DP14: 279.75 | DQ14: 7.75 | DW14: 0.75 | ER14: 114 | EU14: 228.75 | EV14: =SUM(B14:EU14) -> 1102.33 | EW14: 1102.33 | EZ14: Bénévoles (cf RA ABA) : | FB14: =C64 -> 9944.25 | FC14: postes à plein temps = | FE14: =FB14/1900 -> 5.2338158
A15: Merzouk Séverine | B15: 28.5 | C15: 13.25 | D15: 79 | E15: 9.25 | F15: 99 | G15: 7.75 | H15: 284 | P15: 88.75 | Q15: 6 | R15: 9 | S15: 13.25 | V15: 15.75 | BP15: 10.5 | BT15: 40 | CB15: 12.5 | CC15: 35 | CF15: 0.25 | CR15: 12 | CS15: 0.75 | CX15: 36 | CY15: 2.75 | DI15: 8.75 | DP15: 43.75 | DQ15: 41.5 | DR15: 9.75 | DT15: 18.25 | DV15: 15 | ER15: 104.5 | EU15: 4 | EV15: =SUM(B15:EU15) -> 1048.75 | EW15: 1048.75 | EY15: Bénévoles hors honorifiques (OFAS) | FB15: =C65 -> 9779.25 | FC15: postes à plein temps = | FE15: =I65 -> 5.1469737
A16: Othenin Roberto | AD16: 3.5 | AE16: 22.75 | AF16: 176 | AM16: 0.25 | AO16: 10 | BP16: 4 | BY16: 1.25 | CB16: 1 | CX16: 5.6 | DQ16: 4.75 | EV16: =SUM(B16:EU16) -> 229.1 | EW16: 229.1 | EY16: Heures "absences payées" (vacances…) | FB16: =SUM(EU27+ER27+DQ27+DP27+CX27+CR27+CE27) -> 5603 | FC16: 5603 | FD16: pour sauvegarde
A17: Pillet Anne | B17: 23.5 | I17: 1 | O17: 3.5 | P17: 1 | Y17: 2 | AD17: 20.5 | AO17: 17 | AP17: 32 | AQ17: 2.25 | AS17: 0.5 | AU17: 5.25 | AW17: 2.75 | AX17: 10 | BA17: 11.25 | BD17: 1.5 | BE17: 2 | BK17: 0.5 | BP17: 6.75 | BQ17: 41.75 | BR17: 6.25 | BS17: 1 | BT17: 1.75 | BV17: 27 | BX17: 7.25 | BY17: 2.75 | CA17: 169.75 | CB17: 426.5 | CC17: 55.25 | CE17: 219.5 | CP17: 0.5 | CR17: 8 | CX17: 57.6 | DG17: 0.5 | DL17: 1.5 | DM17: 0.25 | DP17: 226.5 | DQ17: 46.5 | DS17: 1 | DU17: 1.75 | ED17: 6.5 | EE17: 36.75 | EF17: 39 | EJ17: 48 | EO17: 35.5 | EP17: 1 | ER17: 252 | EU17: 4 | EV17: =SUM(B17:EU17) -> 1868.85 | EW17: 1868.85 | EY17: soit Z, V, P, M, F, C, A
A18: Rérat Cédric | I18: 12.75 | V18: 0.5 | AO18: 33.25 | AQ18: 0.5 | AT18: 1 | AU18: 2.25 | AX18: 0.5 | BA18: 69.25 | BB18: 39 | BC18: 396.75 | BD18: 33.75 | BE18: 70.75 | BF18: 191 | BG18: 99.5 | BJ18: 0.75 | BK18: 14.75 | BL18: 38.5 | BM18: 0.75 | BN18: 0.5 | BO18: 1 | BP18: 4.75 | BQ18: 7.75 | BT18: 13.25 | BX18: 9.51 | BY18: 3.5 | CA18: 74.75 | CB18: 293.25 | CC18: 238.5 | CN18: 1 | CR18: 46 | CX18: 72 | DK18: 1.75 | DM18: 3.75 | DN18: 5 | DP18: 8 | DQ18: 0.75 | EF18: 109.75 | EJ18: 1.25 | EK18: 4.25 | EQ18: 4.25 | ER18: 176 | ES18: 1 | EV18: =SUM(B18:EU18) -> 2087.01 | EW18: 2087.01 | EY18: Heures pour administration/overhead | FB18: =EV27-FB16-'Heures productives'!EV48-'Heures productives'!EV33-'Heures productives'!EV34-'Heures productives'!EV35-'Heures productives'!EV36-'Heures productives'!EV37-'Heures productives'!EV38-'Heures productives'!EV39-'Heures productives'!EV40 -> 16822.29
A19: Rossier Christophe | AD19: 54.75 | AE19: 261 | AF19: 411.5 | AH19: 64 | AI19: 13.5 | AJ19: 9.5 | AK19: 3 | AL19: 7.25 | AM19: 28.5 | AO19: 30.75 | BP19: 63.5 | BX19: 7.13 | BY19: 17 | CA19: 9 | CB19: 78.25 | CC19: 21.25 | CR19: 12 | CV19: 1.5 | CX19: 48 | DI19: 6.5 | DJ19: 7.5 | DP19: 24 | DQ19: 56.25 | DV19: 11 | DW19: 27.75 | DZ19: 18.5 | ER19: 128 | EV19: =SUM(B19:EU19) -> 1420.88 | EW19: 1420.88
A20: Fleuret Thi Hanh | B20: 37.5 | I20: 12 | J20: 11 | L20: 0.25 | AC20: 1.25 | AD20: 0.25 | AO20: 4.75 | AS20: 1.5 | AT20: 1 | AU20: 0.5 | BA20: 1 | BC20: 183.5 | BE20: 0.25 | BF20: 305.75 | BH20: 278 | BK20: 80.5 | BL20: 47.5 | BM20: 15.5 | BO20: 5.75 | BQ20: 21.5 | BT20: 52.63 | BX20: 1.75 | BY20: 2.5 | BZ20: 0.25 | CB20: 14.5 | CC20: 67.25 | CH20: 4 | CR20: 8 | CX20: 50.4 | CY20: 1.5 | CZ20: 2.25 | DA20: 2.75 | DJ20: 1 | DN20: 5.25 | DO20: 10.75 | DP20: 12 | DQ20: 52.25 | DV20: 1 | DZ20: 0.5 | EA20: 2.25 | EG20: 10.75 | EQ20: 8 | ER20: 144 | EV20: =SUM(B20:EU20) -> 1464.78 | EW20: 1464.78
A21: Meyrat Jean-Marc | B21: 3.75 | X21: 117.5 | Y21: 108.25 | Z21: 125 | AA21: 14.25 | AB21: 4.75 | AE21: 16.25 | AP21: 486 | AX21: 5 | AZ21: 5.5 | BE21: 2.5 | BG21: 80 | BM21: 7.75 | BQ21: 4.75 | BT21: 94.38 | BU21: 43.75 | BV21: 15.25 | BW21: 11.25 | CA21: 20 | CB21: 137 | CC21: 13.5 | CR21: 29.5 | CX21: 57.6 | DP21: 46.5 | DQ21: 4.5 | EA21: 1.5 | EG21: 15 | EL21: 9.5 | EN21: 28 | ER21: 167 | EV21: =SUM(B21:EU21) -> 1675.48 | EW21: 1675.48
A22: Paul Bertram | B22: 7.5 | G22: 0.75 | I22: 20 | J22: 70 | K22: 14.75 | L22: 3.25 | O22: 10 | AB22: 26.25 | AD22: 0.75 | AO22: 1.5 | AQ22: 6.5 | AR22: 0.5 | BA22: 7 | BC22: 17.75 | BE22: 14.25 | BF22: 0.25 | BG22: 74 | BH22: 2.75 | BI22: 49.75 | BK22: 58 | BL22: 182.25 | BM22: 15 | BO22: 23.5 | BQ22: 7.5 | BR22: 0.25 | BS22: 8.25 | BX22: 3 | BY22: 3.5 | BZ22: 0.25 | CB22: 11.5 | CC22: 60.75 | CG22: 2.75 | CL22: 2.25 | CR22: 8 | CT22: 3.5 | CX22: 36 | DC22: 28.5 | DD22: 2 | DG22: 15 | DH22: 1.5 | DM22: 1 | DN22: 0.75 | DQ22: 45.5 | DS22: 1 | EA22: 7 | EB22: 2 | EC22: 8.75 | EE22: 9.75 | EH22: 1.5 | EI22: 0.75 | EJ22: 7.25 | EM22: 1.25 | EQ22: 2.5 | ER22: 140 | ET22: 0.75 | EU22: 20 | EV22: =SUM(B22:EU22) -> 1050.5 | EW22: 1050.5
A23: Mohnhaupt Martin | CD23: 409 | EV23: =SUM(B23:EU23) -> 409 | EW23: 409
A24: Luc Fontoliet | Z24: 195.45 | EV24: =SUM(B24:EU24) -> 195.45 | EW24: 195.45
A25: Klappenbach Sacsahuaman | M25: 125.5 | N25: 8.5 | AY25: 88 | CI25: 2.5 | DE25: 2.5 | EV25: =SUM(B25:EU25) -> 227 | EW25: 227 | EX25: =SUM(EW2:EW25) -> 24522.89
A26: Bénévoles "actifs" | C26: Dès 2016 ajouter ici les heures des bénévoles pouvant être reconnus "actifs" selon les critères de l'OFAS cf. doc : | L26: ..\..\Informations_pour_realisation\BBR-heures-productives.docx | R26: puis soustraire ces heures pour le RA ABA qui les inclut déjà dans son décompte des heures réalisées par les bénévoles
A27: Total | B27: =SUM(B2:B25) -> 513.75 | C27: =SUM(C2:C25) -> 26.25 | D27: =SUM(D2:D25) -> 156 | E27: =SUM(E2:E25) -> 19.75 | F27: =SUM(F2:F25) -> 503.5 | G27: =SUM(G2:G25) -> 9.75 | H27: =SUM(H2:H25) -> 1189.5 | I27: =SUM(I2:I25) -> 49.5 | ... EU27: =SUM(EU2:EU25) -> 300.75 | EV27: =SUM(B27:EU27) -> 24522.89 | EW27: =SUM(EV2:EV25) -> 24522.89
A28: Total | B28: 510 | C28: 26.25 | D28: 156 | E28: 19.75 | F28: 503.5 | G28: 9.75 | H28: 1189.5 | I28: 49.5 | J28: 81.25 | K28: 14.75 | L28: 3.5 | M28: 163.5 | N28: 9.5 | O28: 17 | P28: 143.5 | Q28: 10 | R28: 68.5 | S28: 15.25 | T28: 0.5 | U28: 2.5 | V28: 160.75 | W28: 3.75 | X28: 133.75 | Y28: 126.25 | Z28: 320.45 | AA28: 24.5 | AB28: 31 | AC28: 1.25 | AD28: 348.5 | AE28: 1054.5 | AF28: 1755.75 | AG28: 268 | AH28: 152.5 | AI28: 24.75 | AJ28: 20 | AK28: 3 | AL28: 17.25 | AM28: 42.75 | AN28: 2 | AO28: 216.38 | AP28: 570.5 | AQ28: 908.75 | AR28: 265.25 | AS28: 175 | AT28: 107 | AU28: 175.75 | AV28: 0.75 | AW28: 2.75 | AX28: 31.25 | AY28: 125.5 | AZ28: 6.75 | BA28: 192 | BB28: 40.25 | BC28: 1315 | BD28: 38 | BE28: 119.5 | BF28: 613.25 | BG28: 270.5 | BH28: 280.75 | BI28: 49.75 | BJ28: 0.75 | BK28: 203.25 | BL28: 329.25 | BM28: 49.5 | BN28: 0.5 | BO28: 34.75 | BP28: 210.5 | BQ28: 113.38 | BR28: 6.5 | BS28: 9.25 | BT28: 243.52 | BU28: 198.25 | BV28: 43 | BW28: 41 | BX28: 57.91 | BY28: 101.25 | BZ28: 1.75 | CA28: 382.25 | CB28: 1330.5 | CC28: 813.25 | CD28: 409.75 | CE28: 405.5 | CF28: 1.5 | CG28: 2.75 | CH28: 4 | CI28: 2.5 | CJ28: 31.25 | CK28: 17 | CL28: 2.25 | CM28: 3.5 | CN28: 2.25 | CO28: 2.5 | CP28: 0.5 | CQ28: 25 | CR28: 278.25 | CS28: 7.25 | CT28: 3.5 | CU28: 0.5 | CV28: 5 | CW28: 5.75 | CX28: 802 | CY28: 4.25 | CZ28: 2.25 | DA28: 2.75 | DB28: 0 | DC28: 28.5 | DD28: 2 | DE28: 2.5 | DF28: 0 | DG28: 15.5 | DH28: 1.5 | DI28: 21 | DJ28: 8.5 | DK28: 3.5 | DL28: 2.5 | DM28: 11.25 | DN28: 14.75 | DO28: 10.75 | DP28: 922.5 | DQ28: 562 | DR28: 13.25 | DS28: 127.25 | DT28: 151.25 | DU28: 44.5 | DV28: 81 | DW28: 29.75 | DX28: 26.75 | DY28: 0.5 | DZ28: 19 | EA28: 10.75 | EB28: 4.75 | EC28: 8.75 | ED28: 6.5 | EE28: 236.75 | EF28: 148.75 | EG28: 25.75 | EH28: 1.5 | EI28: 0.75 | EJ28: 56.5 | EK28: 4.25 | EL28: 9.5 | EM28: 1.25 | EN28: 28 | EO28: 35.5 | EP28: 1 | EQ28: 18 | ER28: 2332 | ES28: 9.75 | ET28: 0.75 | EU28: 300.75 | EV28: 24522.89 | EW28: Ligne pour vérification des totaux et calculs divers (copier et collage spécial - valeur, de la ligne précédente)
A31: Hors heures des professionnels de bibliothèque
A32: Boulsa Bénévolat | DB32: 0.75 | DF32: 3.75 | EV32: =SUM(B32:EU32) -> 4.5
A33: reliure bénévoles | BE33: 28.5 | DM33: 14.25 | EV33: =SUM(B33:EU33) -> 42.75
EX36: =EV27-EU27-ER27-DQ27-DP27-CX27-CR27-CE27-CB27 -> 17589.39
A38: Heures pour travail AI | B38: 0 | C38: rien en 2014, se valide en recherchant les codes AI dans la première ligne du tableau
A41: Pour info :
A42: Explication des couleurs : | B42: Totaux
B43: Payés à l'heure
B44: Handicapés de la vue
B45: Travaux bénévoles hors saisie des heures travaillées à la BBR
B46: Heures absences payées
A50: Calcul du travail des bénévoles | C50: Pour les bénévoles : 1 plein temps = | F50: 1900
...

Sheet Heures productives
A1: Collaborateur | B1: 1 | C1: 11C | D1: 11N | E1: 11NC | F1: 11S | G1: 12C | H1: 12S | I1: 13 | J1: 13B | K1: 13C | L1: 13D | M1: 14B | N1: 14D | O1: 16 | P1: 16A | Q1: 16N | R1: 17 | S1: 17E | T1: 18E | U1: 18I | V1: 19 | W1: 1BBR-B | X1: 2 | Y1: 21 | Z1: 24 | AA1: 27 | AB1: 29 | AC1: 2BBR | AD1: 4 | AE1: 41N | AF1: 42N | AG1: 43N | AH1: 44 | AI1: 45 | AJ1: 46C | AK1: 46F | AL1: 46N | AM1: 47 | AN1: 47E | AO1: 49 | AP1: 5 | AQ1: 51 | AR1: 52 | AS1: 53 | AT1: 54 | AU1: 55 | AV1: 55A | AW1: 55E | AX1: 55F | AY1: 56 | AZ1: 5I | BA1: 6 | BB1: 60 | BC1: 61 | BD1: 62 | BE1: 63 | BF1: 64 | BG1: 64A | BH1: 65A | BI1: 65B | BJ1: 67 | BK1: 68 | BL1: 69 | BM1: 69P | BN1: 6DI | BO1: 6I | BP1: 71 | BQ1: 72 | BR1: 72CH | BS1: 72I | BT1: 73 | BU1: 73F | BV1: 74 | BW1: 75 | BX1: 76 | BY1: 76A | BZ1: 76B | CA1: 77 | CB1: 78 | CC1: 79 | CD1: 7I | CE1: A | CF1: A1 | CG1: A13CAL | CH1: A13RA | CI1: A14 | CJ1: A16A | CK1: A16ARA | CL1: A1CAL | CM1: A1RA | CN1: A7CAL | CO1: A7RA | CP1: A7S | CQ1: B1 | CR1: C | CS1: C1 | CT1: C13 | CU1: C7 | CV1: C73 | CW1: CCA24 | CX1: F | CY1: F1 | CZ1: F13 | DA1: F13A | DB1: F13B | DC1: F13CO | DD1: F13FSA | DE1: F14A | DF1: F1B | DG1: F1CO | DH1: F1FSA | DI1: F1VG | DJ1: F4VG | DK1: F7 | DL1: F7A | DM1: F7CO | DN1: F7VG | DO1: I | DP1: M | DQ1: P | DR1: P1 | DS1: P1A | DT1: P1EP | DU1: P1R | DV1: P1VF | DW1: P4 | DX1: P4EP | DY1: P4SD | DZ1: P4VF | EA1: P51 | EB1: P5BV | EC1: P5EP | ED1: P5P | EE1: P5T | EF1: P6A | EG1: P6BT | EH1: P6BV | EI1: P6P | EJ1: P6T | EK1: P6Z | EL1: P72A | EM1: P7C | EN1: P7COM | EO1: P7P | EP1: P7R | EQ1: P7VF | ER1: V | ES1: V1 | ET1: V4G | EU1: Z | EV1: Total
A2: Anderfuhren Sandrine | B2: 3.75 | AM2: 1.25 | AP2: 1.5 | AQ2: 50 | AR2: 20.5 | AS2: 1.75 | BC2: 16.25 | BE2: 1.5 | BF2: 9.75 | BG2: 1.5 | BL2: 5.75 | BM2: 10.5 | BQ2: 1.25 | BT2: 10.51 | BU2: 139 | DM2: 2 | EV2: =SUM(B2:EU2) -> 276.76 | EW2: 276.76
A3: Baratti Graziano | I3: 1.75 | M3: 0.25 | N3: 0.5 | O3: 0.25 | AO3: 9 | AQ3: 41.75 | AR3: 4.75 | AS3: 10.5 | AT3: 4 | AU3: 1.75 | AY3: 0.75 | BA3: =103.5+37 -> 140.5 | BB3: 1.25 | BC3: 700.75 | BD3: 2.75 | BE3: 27.75 | BF3: 106.5 | BG3: 15.5 | BK3: 49.25 | BL3: 55.25 | BO3: 4.5 | BP3: 10.25 | BQ3: 15.25 | BT3: 14.25 | BX3: 4.5 | BY3: 15.25 | BZ3: 1.25 | CA3: 9 | CD3: 0.75 | CN3: 1.25 | DM3: 0.5 | DN3: 2 | EQ3: 2.75 | EV3: =SUM(B3:EU3) -> 1256.25 | EW3: 1256.25
A4: Bolay Valérie | B4: =104.5+28.5 -> 133 | C4: 13 | D4: 49 | E4: 10.5 | F4: 121.75 | H4: 311.25 | O4: 1.75 | P4: 1 | Q4: 4 | V4: 5.5 | Y4: 5 | AA4: 9.5 | BK4: 0.25 | BP4: 19 | BT4: 6.25 | BY4: 2.25 | CJ4: 18.25 | CK4: 6.25 | CM4: 3.5 | CQ4: 7.75 | CS4: 0.75 | DI4: 4.75 | DR4: 2.5 | DS4: 111.25 | DT4: 104 | DU4: 30.75 | DV4: 4 | ES4: 8.75 | EV4: =SUM(B4:EU4) -> 995.5 | EW4: 995.5
A5: Castello Donja | B5: 1 | F5: 31.5 | H5: 119.25 | BP5: 2.25 | EV5: =SUM(B5:EU5) -> 154 | EW5: 154
A6: Chatelain Antonin | AD6: =21.25+38.25 -> 59.5 | AE6: 234.5 | AF6: 442 | AH6: 23.5 | AI6: 0.5 | AJ6: 3 | AO6: 0.25 | BP6: 0.5 | BQ6: 7.13 | BY6: 24 | CA6: 1.5 | EV6: =SUM(B6:EU6) -> 796.38 | EW6: 796.38
A7: Chatenoux Didier | AD7: =27+43.75 -> 70.75 | AE7: 387.75 | AF7: 353.5 | AG7: 268 | AI7: 3 | AJ7: 2 | AL7: 7.5 | AM7: 2.75 | AN7: 2 | AO7: 50.5 | BP7: 45 | BX7: 5.63 | EV7: =SUM(B7:EU7) -> 1198.38 | EW7: 1198.38
A8: Dos Santos Martins Carlos | AP8: =19+23.5 -> 42.5 | AQ8: 414 | AR8: 155 | AS8: 53.75 | AT8: 50.5 | AU8: 138.5 | AX8: 12.25 | AY8: 8.25 | BQ8: 3 | BT8: 4.5 | BU8: 15.5 | DM8: 3 | EV8: =SUM(B8:EU8) -> 900.75 | EW8: 900.75
A9: Favre Corinne | B9: =294.25+40.25 -> 334.5 | G9: 1.25 | H9: 171 | I9: 2 | J9: 0.25 | M9: 37.75 | N9: 0.5 | O9: 1.5 | P9: 19.75 | R9: 2.5 | S9: 2 | T9: 0.5 | U9: 2.5 | V9: 100.5 | X9: 16.25 | Y9: 11 | AA9: 0.75 | BP9: 18.5 | BT9: 3.75 | BW9: 0.5 | BX9: 11.51 | CA9: 32.5 | CF9: 1.25 | CJ9: 13 | CK9: 10.75 | CO9: 2.5 | CQ9: 2.75 | CS9: 5.75 | CU9: 0.5 | CW9: 5.75 | DK9: 1.75 | DL9: 1 | DN9: 1.75 | DR9: 1 | DS9: 8.75 | DT9: 10.25 | DU9: 12 | EQ9: 0.5 | EV9: =SUM(B9:EU9) -> 850.51 | EW9: 850.51
A10: Galley Laurent | AI10: 0.75 | AO10: 3.75 | AP10: =33.5+22 -> 55.5 | AQ10: 393.75 | AR10: 84.5 | AS10: 107 | AT10: 50.5 | AU10: 27.5 | AV10: 0.75 | AX10: 3.5 | AY10: 28.5 | AZ10: 1.25 | BE10: 0.5 | BQ10: 3.5 | BT10: 2.25 | BV10: 0.75 | BX10: 2 | BY10: 1.75 | DM10: 0.75 | EV10: =SUM(B10:EU10) -> 768.75 | EW10: 768.75
A11: Geuggis Gilles | AD11: =16.5+7.5 -> 24 | AE11: 52.75 | AF11: 218.75 | AH11: 35.25 | AI11: 4 | AM11: 2 | AO11: 6.75 | BP11: 12 | BX11: 5.63 | CA11: 8.25 | CV11: 3.5 | EV11: =SUM(B11:EU11) -> 372.88 | EW11: 372.88
A12: Harth Eric | AD12: =152.5+24 -> 176.5 | AJ12: 3.75 | AM12: 8 | AO12: 0.25 | BP12: 2 | CA12: 56.75 | DT12: 3 | DW12: 1.25 | DX12: 26.75 | DY12: 0.5 | EB12: 2.75 | EE12: 190.25 | EV12: =SUM(B12:EU12) -> 471.75 | EW12: 471.75
A13: Holenweg Pascale | B13: =10.5+9.25 -> 19.75 | D13: 28 | F13: 251.25 | H13: 304 | P13: 33 | R13: 57 | V13: 38.5 | BP13: 9.5 | BW13: 29.25 | CQ13: 14.5 | DI13: 1 | DS13: 5.25 | DT13: 15.75 | DV13: 50 | EV13: =SUM(B13:EU13) -> 856.75 | EW13: 856.75
A14: Kuhn Christian | AD14: =51.5+16 -> 67.5 | AE14: 79.5 | AF14: 154 | AH14: 29.75 | AI14: 3 | AJ14: 1.75 | AL14: 2.5 | AO14: 48.63 | BP14: 2 | BY14: 27.5 | CA14: 0.75 | DW14: 0.75 | EV14: =SUM(B14:EU14) -> 417.63 | EW14: 417.63
A15: Merzouk Séverine | B15: =28.5+12.5 -> 41 | C15: 13.25 | D15: 79 | E15: 9.25 | F15: 99 | G15: 7.75 | H15: 284 | P15: 88.75 | Q15: 6 | R15: 9 | S15: 13.25 | V15: 15.75 | BP15: 10.5 | BT15: 40 | CF15: 0.25 | CS15: 0.75 | CY15: 2.75 | DI15: 8.75 | DR15: 9.75 | DT15: 18.25 | DV15: 15 | EV15: =SUM(B15:EU15) -> 772 | EW15: 772
A16: Othenin Roberto | AD16: =3.5+1 -> 4.5 | AE16: 22.75 | AF16: 176 | AM16: 0.25 | AO16: 10 | BP16: 4 | BY16: 1.25 | EV16: =SUM(B16:EU16) -> 218.75 | EW16: 218.75
A17: Pillet Anne | B17: 23.5 | I17: 1 | O17: 3.5 | P17: 1 | Y17: 2 | AD17: 20.5 | AO17: 17 | AP17: 32 | AQ17: 2.25 | AS17: 0.5 | AU17: 5.25 | AW17: 2.75 | AX17: 10 | BA17: 11.25 | BD17: 1.5 | BE17: 2 | BK17: 0.5 | BP17: 6.75 | BQ17: 41.75 | BR17: 6.25 | BS17: 1 | BT17: 1.75 | BV17: 27 | BX17: 7.25 | BY17: 2.75 | CA17: 169.75 | CP17: 0.5 | DG17: 0.5 | DL17: 1.5 | DM17: 0.25 | DS17: 1 | DU17: 1.75 | ED17: 6.5 | EE17: 36.75 | EF17: 39 | EJ17: 48 | EO17: 35.5 | EP17: 1 | EV17: =SUM(B17:EU17) -> 573 | EW17: 573
A18: Rérat Cédric | I18: 12.75 | V18: 0.5 | AD18: 40 | AO18: 33.25 | AP18: 70 | AQ18: 0.5 | AT18: 1 | AU18: 2.25 | AX18: 0.5 | BA18: =69.25+40 -> 109.25 | BB18: 39 | BC18: 396.75 | BD18: 33.75 | BE18: 70.75 | BF18: 191 | BG18: 99.5 | BJ18: 0.75 | BK18: 14.75 | BL18: 38.5 | BM18: 0.75 | BN18: 0.5 | BO18: 1 | BP18: 4.75 | BQ18: 7.75 | BT18: 13.25 | BX18: 9.51 | BY18: 3.5 | CA18: 74.75 | CN18: 1 | DK18: 1.75 | DM18: 3.75 | DN18: 5 | EF18: 109.75 | EJ18: 1.25 | EK18: 4.25 | EQ18: 4.25 | ES18: 1 | EV18: =SUM(B18:EU18) -> 1402.51 | EW18: 1402.51
A19: Rossier Christophe | AD19: =54.75+39 -> 93.75 | AE19: 261 | AF19: 411.5 | AH19: 64 | AI19: 13.5 | AJ19: 9.5 | AK19: 3 | AL19: 7.25 | AM19: 28.5 | AO19: 30.75 | BP19: 63.5 | BX19: 7.13 | BY19: 17 | CA19: 9 | CV19: 1.5 | DI19: 6.5 | DJ19: 7.5 | DV19: 11 | DW19: 27.75 | DZ19: 18.5 | EV19: =SUM(B19:EU19) -> 1092.13 | EW19: 1092.13
A20: Fleuret Thi Hanh | B20: 37.5 | I20: 12 | J20: 11 | L20: 0.25 | AC20: 1.25 | AD20: 0.25 | AO20: 4.75 | AS20: 1.5 | AT20: 1 | AU20: 0.5 | BA20: 1 | BC20: 183.5 | BE20: 0.25 | BF20: 305.75 | BH20: 278 | BK20: =80.5+14.5 -> 95 | BL20: 47.5 | BM20: 15.5 | BO20: 5.75 | BQ20: 21.5 | BT20: 52.63 | BX20: 1.75 | BY20: 2.5 | BZ20: 0.25 | CH20: 4 | CY20: 1.5 | CZ20: 2.25 | DA20: 2.75 | DJ20: 1 | DN20: 5.25 | DO20: 10.75 | DV20: 1 | DZ20: 0.5 | EA20: 2.25 | EG20: 10.75 | EQ20: 8 | EV20: =SUM(B20:EU20) -> 1130.88 | EW20: 1130.88
A21: Meyrat Jean-Marc | B21: 3.75 | X21: 117.5 | Y21: 108.25 | Z21: 125 | AA21: 14.25 | AB21: 4.75 | AE21: 16.25 | AP21: =486+69 -> 555 | AX21: 5 | AZ21: 5.5 | BE21: 2.5 | BG21: 80 | BM21: 7.75 | BQ21: 4.75 | BT21: 94.38 | BU21: 43.75 | BV21: 15.25 | BW21: 11.25 | CA21: 20 | EA21: 1.5 | EG21: 15 | EL21: 9.5 | EN21: 28 | EV21: =SUM(B21:EU21) -> 1288.88 | EW21: 1288.88
A22: Paul Bertram | B22: 7.5 | G22: 0.75 | I22: 20 | J22: 70 | K22: 14.75 | L22: 3.25 | O22: 10 | AB22: 26.25 | AD22: 0.75 | AO22: 1.5 | AQ22: 6.5 | AR22: 0.5 | BA22: 7 | BC22: 17.75 | BE22: 14.25 | BF22: 0.25 | BG22: 74 | BH22: 2.75 | BI22: 49.75 | BK22: =58+11.5 -> 69.5 | BL22: 182.25 | BM22: 15 | BO22: 23.5 | BQ22: 7.5 | BR22: 0.25 | BS22: 8.25 | BX22: 3 | BY22: 3.5 | BZ22: 0.25 | CG22: 2.75 | CL22: 2.25 | CT22: 3.5 | DC22: 28.5 | DD22: 2 | DG22: 15 | DH22: 1.5 | DM22: 1 | DN22: 0.75 | DS22: 1 | EA22: 7 | EB22: 2 | EC22: 8.75 | EE22: 9.75 | EH22: 1.5 | EI22: 0.75 | EJ22: 7.25 | EM22: 1.25 | EQ22: 2.5 | ET22: 0.75 | EV22: =SUM(B22:EU22) -> 740.25 | EW22: 740.25
A23: Mohnhaupt Martin | CD23: 409 | EV23: =SUM(B23:EU23) -> 409 | EW23: 409
A24: Luc Fontoliet | Z24: 195.45 | EV24: =SUM(B24:EU24) -> 195.45 | EW24: 195.45
A25: Klappenbach Sacsahuaman | M25: 125.5 | N25: 8.5 | AY25: 88 | CI25: 2.5 | DE25: 2.5 | EV25: =SUM(B25:EU25) -> 227 | EW25: 227 | EX25: =SUM(EW2:EW25) -> 17366.14
A26: Total | B26: =SUM(B2:B25) -> 605.25 | C26: =SUM(C2:C25) -> 26.25 | D26: =SUM(D2:D25) -> 156 | E26: =SUM(E2:E25) -> 19.75 | F26: =SUM(F2:F25) -> 503.5 | G26: =SUM(G2:G25) -> 9.75 | H26: =SUM(H2:H25) -> 1189.5 | I26: =SUM(I2:I25) -> 49.5 | ... S26: =SUM(S2:S25) -> 15.25 | V26: =SUM(V2:V25) -> 160.75 | W26: =SUM(W2:W25) -> 0 | AB26: =SUM(AB2:AB25) -> 31 | AC26: =SUM(AC2:AC25) -> 1.25 | AD26: =SUM(AD2:AD25) -> 558 | AE26: =SUM(AE2:AE25) -> 1054.5 | AF26: =SUM(AF2:AF25) -> 1755.75 | AG26: =SUM(AG2:AG25) -> 268 | AH26: =SUM(AH2:AH25) -> 152.5 | AI26: =SUM(AI2:AI25) -> 24.75 | ... BJ26: =SUM(BJ2:BJ25) -> 0.75 | BL26: =SUM(BL2:BL25) -> 329.25 | BM26: =SUM(BM2:BM25) -> 49.5 | BN26: =SUM(BN2:BN25) -> 0.5 | BO26: =SUM(BO2:BO25) -> 34.75 | BU26: =SUM(BU2:BU25) -> 198.25 | BX26: =SUM(BX2:BX25) -> 57.91 | BY26: =SUM(BY2:BY25) -> 101.25 | BZ26: =SUM(BZ2:BZ25) -> 1.75 | CD26: =SUM(CD2:CD25) -> 409.75 | CF26: =SUM(CF2:CF25) -> 1.5 | CG26: =SUM(CG2:CG25) -> 2.75 | CH26: =SUM(CH2:CH25) -> 4 | CK26: =SUM(CK2:CK25) -> 17 | CL26: =SUM(CL2:CL25) -> 2.25 | CM26: =SUM(CM2:CM25) -> 3.5 | CN26: =SUM(CN2:CN25) -> 2.25 | CO26: =SUM(CO2:CO25) -> 2.5 | CS26: =SUM(CS2:CS25) -> 7.25 | CT26: =SUM(CT2:CT25) -> 3.5 | CU26: =SUM(CU2:CU25) -> 0.5 | DO26: =SUM(DO2:DO25) -> 10.75 | DR26: =SUM(DR2:DR25) -> 13.25 | DS26: =SUM(DS2:DS25) -> 127.25 | DT26: =SUM(DT2:DT25) -> 151.25 | DU26: =SUM(DU2:DU25) -> 44.5 | DV26: =SUM(DV2:DV25) -> 81 | DW26: =SUM(DW2:DW25) -> 29.75 | DX26: =SUM(DX2:DX25) -> 26.75 | DY26: =SUM(DY2:DY25) -> 0.5 | DZ26: =SUM(DZ2:DZ25) -> 19 | EB26: =SUM(EB2:EB25) -> 4.75 | EC26: =SUM(EC2:EC25) -> 8.75 | ED26: =SUM(ED2:ED25) -> 6.5 | EE26: =SUM(EE2:EE25) -> 236.75 | EF26: =SUM(EF2:EF25) -> 148.75 | EG26: =SUM(EG2:EG25) -> 25.75 | EH26: =SUM(EH2:EH25) -> 1.5 | EI26: =SUM(EI2:EI25) -> 0.75 | ... EK26: =SUM(EK2:EK25) -> 4.25 | EM26: =SUM(EM2:EM25) -> 1.25 | EN26: =SUM(EN2:EN25) -> 28 | EO26: =SUM(EO2:EO25) -> 35.5 | EP26: =SUM(EP2:EP25) -> 1 | EQ26: =SUM(EQ2:EQ25) -> 18 | ES26: =SUM(ES2:ES25) -> 9.75 | ET26: =SUM(ET2:ET25) -> 0.75 | EV26: =SUM(B26:EU26) -> 15268.54 | EW26: =SUM(EV2:EV25) -> 17366.14
A27: Total | B27: 605.25 | C27: 26.25 | D27: 156 | E27: 19.75 | F27: 503.5 | G27: 9.75 | H27: 1189.5 | I27: 49.5 | J27: 81.25 | K27: 14.75 | L27: 3.5 | M27: 163.5 | N27: 9.5 | O27: 17 | P27: 143.5 | Q27: 10 | R27: 68.5 | S27: 15.25 | V27: 160.75 | W27: 0 | AB27: 31 | AC27: 1.25 | AD27: 558 | AE27: 1054.5 | AF27: 1755.75 | AG27: 268 | AH27: 152.5 | AI27: 24.75 | AJ27: 20 | AK27: 3 | AL27: 17.25 | AM27: 42.75 | AN27: 2 | AO27: 216.38 | AP27: 756.5 | AQ27: 908.75 | AR27: 265.25 | AS27: 175 | AT27: 107 | AU27: 175.75 | AV27: 0.75 | AW27: 2.75 | AX27: 31.25 | AY27: 125.5 | AZ27: 6.75 | BA27: 269 | BB27: 40.25 | BC27: 1315 | BD27: 38 | BE27: 119.5 | BF27: 613.25 | BG27: 270.5 | BH27: 280.75 | BI27: 49.75 | BJ27: 0.75 | BL27: 329.25 | BM27: 49.5 | BN27: 0.5 | BO27: 34.75 | BU27: 198.25 | BX27: 57.91 | BY27: 101.25 | BZ27: 1.75 | CD27: 409.75 | CF27: 1.5 | CG27: 2.75 | CH27: 4 | CK27: 17 | CL27: 2.25 | CM27: 3.5 | CN27: 2.25 | CO27: 2.5 | CS27: 7.25 | CT27: 3.5 | CU27: 0.5 | DO27: 10.75 | DR27: 13.25 | DS27: 127.25 | DT27: 151.25 | DU27: 44.5 | DV27: 81 | DW27: 29.75 | DX27: 26.75 | DY27: 0.5 | DZ27: 19 | EB27: 4.75 | EC27: 8.75 | ED27: 6.5 | EE27: 236.75 | EF27: 148.75 | EG27: 25.75 | EH27: 1.5 | EI27: 0.75 | EJ27: 56.5 | EK27: 4.25 | EM27: 1.25 | EN27: 28 | EO27: 35.5 | EP27: 1 | EQ27: 18 | ES27: 9.75 | ET27: 0.75 | EV27: 15268.54 | EW27: 17366.14 | EX27: Ligne pour vérification des totaux et calculs divers (copier et collage spécial - valeur, de la ligne précédente)
A30: Heures improductives overhead
A31: Heures pour absences payées (service civile, militaire, maladies…) | CE31: ='Heures brutes'!CE28 -> 405.5 | CR31: ='Heures brutes'!CR28 -> 278.25 | CX31: ='Heures brutes'!CX28 -> 802 | DP31: ='Heures brutes'!DP28 -> 922.5 | DQ31: ='Heures brutes'!DQ28 -> 562 | ER31: ='Heures brutes'!ER28 -> 2332 | EU31: ='Heures brutes'!EU28 -> 300.75 | EV31: =SUM(B31:EU31) -> 5603 | EW31: heures non productives
A32: Heures improductives pour overhead… | CB32: 740.5 | CC32: ='Heures brutes'!CC28 -> 813.25 | EV32: =SUM(B32:EU32) -> 1553.75 | EW32: heures non productives
A33: Relecture de documents internes (orghographe…) | CP33: =SUM(CP2:CP25) -> 0.5 | CQ33: =SUM(CQ2:CQ25) -> 25 | EV33: =SUM(B33:EU33) -> 25.5 | EW33: heures non productives
A34: Conseils orientation en réception | BK34: =SUM(BK2:BK25) -> 229.25 | EV34: =SUM(B34:EU34) -> 229.25 | EW34: heures non productives
A35: Relations publiques ( bibliothèques publiques, consortium, bibliothèques étrangères, CIR) | BQ35: =SUM(BQ2:BQ25) -> 113.38 | BR35: =SUM(BR2:BR25) -> 6.5 | BS35: =SUM(BS2:BS25) -> 9.25 | CV35: =SUM(CV2:CV25) -> 5 | EV35: =SUM(B35:EU35) -> 134.13 | EW35: heures non productives
A36: Représentations externes | BV36: =SUM(BV2:BV25) -> 43 | BW36: =SUM(BW2:BW25) -> 41 | EV36: =SUM(B36:EU36) -> 84 | EW36: heures non productives
A37: Gestion du personnel | CA37: =SUM(CA2:CA25) -> 382.25 | EV37: =SUM(B37:EU37) -> 382.25 | EW37: heures non productives
A38: Manutentions/relectures pour l'ABA | CI38: =SUM(CI2:CI25) -> 2.5 | CJ38: =SUM(CJ2:CJ25) -> 31.25 | EV38: =SUM(B38:EU38) -> 33.75 | EW38: heures non productives
A39: Animation braille | BT39: =SUM(BT2:BT25) -> 243.52 | EV39: =SUM(B39:EU39) -> 243.52 | EW39: heures non productives
A40: Entretien des locaux | BP40: =SUM(BP2:BP25) -> 210.5 | EV40: =SUM(B40:EU40) -> 210.5 | EW40: heures non productives
EV41: =SUM(EV31:EV40) -> 8499.65
A43: Heures improductives à signaler à LM pour transmission ou non au CCA ou CIR | FB43: Prestations facturées totales | FF43: =EV44 -> 120.75
...

Sheet Heures audio produites-recap
A1: Récapitulatif général : | C1: Chiffres de digibook | D1: NetBib | H1: MOT de pass pour modif des cellules protégées = OFAS
D2: titres | E2: heures | F2: minutes | H2: remarques et usage dans la stat ofas
A3: Adjonction totale au catalogue | D3: =D6+D8+D11+D13+D17 -> 537 | E3: =E17+E8+E11+E13-E17+E6 -> 178.71597 | H3: pour validation avec les extractions NetBiblio
D4: soit | E4: XX | H4: !!! En cas de légère différence entre l'info Digibook et NetBiblio, les infos retenues sont celles de NetBiblio. Si la différence est importante, en trouver la source
A6: repiquage anciens enregistrements conservés nouvellement ajoutés à la collection | C6: 0 | D6: 0 | E6: 0 | F6: 0
A8: Total prod BBR (stu+domicile) : | C8: 246 | D8: ='Heures audio prod-extrNetBiblio'!B263 -> 246 | E8: ='Heures audio prod-extrNetBiblio'!M263 -> 71.304861 | H8: à compter dans les heures produites par la BBR et utiliser pour évaluer le temps de travail des bénévoles dans le fichier excel extrait de la saisie des heures (heures produites x 3)
H9: studio | I9: 206 titres, 1439 h. 46 min (NetBib)
H10: domicile | I10: 40 titres, 271 h 33 min (NetBib)
A11: Total copies commerce daisyfiées (=commerce seul) | C11: 119 | D11: ='Heures audio prod-extrNetBiblio'!B388 -> 119 | E11: ='Heures audio prod-extrNetBiblio'!M388 -> 38.601389 | H11: à ajouter aux heures produites par la BBR, idem gros travaux de daisyfication, si très petit, les intégrer simplement dans le total de la prod BBR tel que provenant de Digibook
A13: Total copies hors prod BBR (BSR-LBB…-hors commerce) | C13: 172 | D13: ='Heures audio prod-extrNetBiblio'!B604 -> 172 | E13: ='Heures audio prod-extrNetBiblio'!M604 -> 68.809722 | H13: ne comptabiliser que comme des heure de copies dans entretien ancienne collection
D14: soit | E14: =SUM(E6:E13) -> 178.71597
A16: Productions diverses
A17: Total daisyfication et redaisyfication (de Digibook) qui ne sont pas annoncés dans le catalogue car déjà signalés sous forme de cassette | D17: 0 | E17: 0 | F17: 0 | H17: DANS LA STAT OFAS : à ajouter aux heures produites par la BBR, dans Digibook "dossiers-DAISIFICATIONS…", n'inclut pas les les copies du commerce qui sont comptabilisées dans "commerce"
E18: =E17+(ROUNDDOWN(F17/60,0)) -> 0 | F18: =F17-(ROUNDDOWN(F17/60,0)*60) -> 0
A20: Cas particuliers (Digibook) - à évaluer | D20: 0 | E20: 0 | H20: !!! Synthèse vocale à compter séparément : au cas par cas : 2012
A21: Votations | C21: 5 votations en X exempalires) | D21: 5 | E21: 0.30208333 | H21: à compter dans les heures produites par la BBR et utiliser pour évaluer le temps de travail des bénévoles dans le fichier excel extrait de la saisie des heures (heures XXXX)
A22: autre | B22: 1x Gazette vallon | D22: 1 | E22: 0.020138889
A23: Rapport annuel ABA | D23: 0 | E23: 0 | H23: à compter dans les heures produites par la BBR et utiliser pour évaluer le temps de travail des bénévoles dans le fichier excel extrait de la saisie des heures (heures XXXX)
A24: Calp + catalo thématiques | D24: 4 | E24: 0.73055556 | H24: à compter dans les heures produites par la BBR et utiliser pour évaluer le temps de travail des bénévoles dans le fichier excel extrait de la saisie des heures (heures XXXX)
C25: TOTAL prod div | D25: =SUM(D20:D24) -> 10 | E25: =SUM(E20:E24) -> 1.0527778
A26: Nbr de documents traités par les studios durant l'année | D26: =D24+D23+D22+D21+D20+D17+D13+D11+D8+D6 -> 547
A27: Totaux Divers | F27: comptabiliser toutes les copies qui se font sur les graveurs et les répartir sur les grilles Ofas en fonction de leurs particularités
A28: Productions des bénévoles
A29: Prod par BBR (stu+dom+votations+calp)
A30: Stud + domicile | D30: =D8 -> 246 | E30: =E8 -> 71.304861 | I30: Pour décompte heures prod bénévoles
A31: votations | D31: =D21 -> 5 | E31: =E21 -> 0.30208333 | I31: Pour décompte heures prod bénévoles
A32: autres | D32: =D22 -> 1 | E32: =E22 -> 0.020138889 | I32: Pour décompte heures prod bénévoles
A33: RA ABA | D33: =D23 -> 0 | E33: =E23 -> 0 | I33: Pour décompte heures prod bénévoles
A34: Calp + catalo thématiques | D34: =D24 -> 4 | E34: =E24 -> 0.73055556 | I34: Pour décompte heures prod bénévoles en fonction du réalisateur des documents de l'année
A35: cas particuliers | D35: =D20 -> 0 | E35: =E20 -> 0
D36: =SUM(D30:D35) -> 256 | E36: =SUM(E30:E35) -> 72.357639 | F36: 72.357639
A38: Daisyfications et redaisyf. de livres non annoncés comme nouveautés | D38: =D17+D6 -> 0 | E38: =E17+E6 -> 0 | G38: à utiliser pour remplir la stat prod OFAS et compter comme heure produite par la BBR
A39: commerce | D39: =D11 -> 119 | E39: =E11 -> 38.601389
D40: =SUM(D38:D39) -> 119 | E40: =SUM(E38:E39) -> 38.601389
A42: Prod synthèse vocale | D42: 0 | E42: 0
A44: Echanges
A45: Copies de l'extérieur sans retouches(LBB…) | D45: =D13 -> 172 | E45: =E13 -> 68.809722 | F45: =F14 -> 0 | G45: ne comptabiliser que comme des heure de copies dans entretien ancienne collection
E47: =E42+E40+E36+E25+E14 -> 290.72778 | G47: Total prod audio
A628: Donc :
A629: stats ofas, total heures numérisées = | D629: =E17+#REF!+#REF! -> #REF!
...

Sheet Heures audio prod-extrNetBiblio
A1: 1 | B1: No de notice | C1: Auteur | D1: Titre | E1: Nombre de vol./durée | F1: compter le nbr de caractères pour créer la fonction si | G1: extraire les heures | H1: convertir le texte en heures | I1: extraire les minutes | J1: Eliminer le texte min. | K1: convertir en numérique | L1: concaténer les h et min | M1: convertir en nbr et lui donner le fomat numérique [hh]:mm | N1: Note générale | O1: Cote | P1: Fournisseur | Q1: Appartenance
A2: 2 | B2: 7513A100 | C2: Eriksen, Endre Lund | D2: Super | E2: 5 h. 45 min. | F2: =LEN(E2) -> 12 | G2: =IF(F2=12,LEFT(E2,1),LEFT(E2,2)) -> 5 | H2: =VALUE(G2) -> 5 | I2: =RIGHT(E2,7) -> 45 min. | J2: =LEFT(I2,2) -> 45 | K2: =VALUE(J2) -> 45 | L2: =H2&":"&K2 -> 5:45 | M2: =VALUE(L2) -> 0.23958333 | N2: Mme Aline Sauter Caillet, 2015 | O2: 1.99 | P2: BBR-enregistrement à domicile | Q2: BBR
A3: 3 | B3: 7515A100 | C3: Lugon-Moulin, Roland | D3: Double schuss | E3: 8 h. 43 min. | F3: =LEN(E3) -> 12 | G3: =IF(F3=12,LEFT(E3,1),LEFT(E3,2)) -> 8 | H3: =VALUE(G3) -> 8 | I3: =RIGHT(E3,7) -> 43 min. | J3: =LEFT(I3,2) -> 43 | K3: =VALUE(J3) -> 43 | L3: =H3&":"&K3 -> 8:43 | M3: =VALUE(L3) -> 0.36319444 | N3: M. Serge Kneuss, 2014 | O3: 1.1 | P3: BBR-enregistrement à domicile | Q3: BBR
A4: 4 | B4: 7522A100 | C4: Pigani, Paola | D4: N'entre pas dans mon âme avec tes chaussures | E4: 6 h. 08 min. | F4: =LEN(E4) -> 12 | G4: =IF(F4=12,LEFT(E4,1),LEFT(E4,2)) -> 6 | H4: =VALUE(G4) -> 6 | I4: =RIGHT(E4,7) -> 08 min. | J4: =LEFT(I4,2) -> 08 | K4: =VALUE(J4) -> 8 | L4: =H4&":"&K4 -> 6:8 | M4: =VALUE(L4) -> 0.25555556 | N4: Mme Lorenza Eder, 2015 | O4: 1.1 | P4: BBR-enregistrement à domicile | Q4: BBR
A5: 5 | B5: 7524A100 | C5: Arnaud, Claude | D5: Proust contre Cocteau | E5: 5 h. 19 min. | F5: =LEN(E5) -> 12 | G5: =IF(F5=12,LEFT(E5,1),LEFT(E5,2)) -> 5 | H5: =VALUE(G5) -> 5 | I5: =RIGHT(E5,7) -> 19 min. | J5: =LEFT(I5,2) -> 19 | K5: =VALUE(J5) -> 19 | L5: =H5&":"&K5 -> 5:19 | M5: =VALUE(L5) -> 0.22152778 | N5: M. Willy Bulliard, 2015 | O5: 9.82 | P5: BBR-enregistrement à domicile | Q5: BBR
